Workbook

Sheet Drivers
A1: MLKN drivers
A2: $m; rates as decimals
E3: FY28E | F3: FY29E | G3: FY30E | H3: FY31E
A4: Last reported quarter of FY2027 | C4: 0
A5: Shares outstanding, latest 10-Q/10-K cover (m) | C5: 68.123238
A7: Revenue growth, FY2027 quarters vs. same quarter of FY2026 | C7: 0.047
A8: Revenue growth by forecast year | E8: 0.047 | F8: 0.04 | G8: 0.033 | H8: 0.026
A9: Gross margin | C9: 0.3874
A10: SG&A, % of revenue | C10: 0.3078
A11: Other operating expenses, % of revenue | C11: 0.0254
A12: Depreciation and amortization, % of revenue | C12: 0.0386
A13: Capital expenditures, % of revenue | C13: 0.0318
A14: Tax rate | C14: 0.253
A15: Days sales outstanding (on revenue) | C15: 34
A16: Days inventory outstanding (on cost of revenue) | C16: 75.8
A17: Days payables outstanding (on cost of revenue) | C17: 43.3
A18: Shareholder payouts and other financing, % of net income | C18: 1
A19: Interest expense, net, per year ($m) | C19: 69.9
A20: Other non-operating income, per quarter ($m) | C20: 0
... A27: Q4 gross margin (analyst override) | C27: 0.3924

Sheet Quarterly
A1: MLKN quarterly model ($m)
C2: Q1 FY26 | D2: Q2 FY26 | E2: Q3 FY26 | F2: Q4 FY26 | G2: Q1 FY27 | H2: Q2 FY27 | I2: Q3 FY27 | J2: Q4 FY27
C3: A | D3: A | E3: A | F3: A | G3: =IF(1<=Drivers!$C$4,"A","E") | H3: =IF(2<=Drivers!$C$4,"A","E") | I3: =IF(3<=Drivers!$C$4,"A","E") | J3: =IF(4<=Drivers!$C$4,"A","E")
A5: P&L
A6: Rev | C6: 955.7 | D6: 955.2 | E6: 926.6 | F6: =Annual!C6-C6-D6-E6 | G6: =C6*(1+Drivers!$C$7) | H6: =D6*(1+Drivers!$C$7) | I6: =E6*(1+Drivers!$C$7) | J6: =F6*(1+Drivers!$C$7)
A7: COGS | C7: 587.6 | D7: 583 | E7: 573.7 | F7: =Annual!C7-C7-D7-E7 | G7: =G6*(1-Drivers!$C$9) | H7: =H6*(1-Drivers!$C$9) | I7: =I6*(1-Drivers!$C$9) | J7: =J6*(1-Drivers!$C$27)
A8: GP | C8: =C6-C7 | D8: =D6-D7 | E8: =E6-E7 | F8: =F6-F7 | G8: =G6-G7 | H8: =H6-H7 | I8: =I6-I7 | J8: =J6-J7
A9: SG&A | C9: 293.8 | D9: 298.3 | E9: 285.5 | F9: =Annual!C9-C9-D9-E9 | G9: =G6*Drivers!$C$10 | H9: =H6*Drivers!$C$10 | I9: =I6*Drivers!$C$10 | J9: =J6*Drivers!$C$10
A10: Other opex | C10: =C8-C9-C11 | D10: =D8-D9-D11 | E10: =E8-E9-E11 | F10: =F8-F9-F11 | G10: =G6*Drivers!$C$11 | H10: =H6*Drivers!$C$11 | I10: =I6*Drivers!$C$11 | J10: =J6*Drivers!$C$11
A11: EBIT | C11: 53.5 | D11: 48.5 | E11: 44.9 | F11: =Annual!C11-C11-D11-E11 | G11: =G8-G9-G10 | H11: =H8-H9-H10 | I11: =I8-I9-I10 | J11: =J8-J9-J10
A12: Int exp, net | C12: 18.4 | D12: 17.9 | E12: 17.2 | F12: =Annual!C12-C12-D12-E12 | G12: =Drivers!$C$19/4 | H12: =Drivers!$C$19/4 | I12: =Drivers!$C$19/4 | J12: =Drivers!$C$19/4
A13: Other non-op | C13: =C14-C11+C12 | D13: =D14-D11+D12 | E13: =E14-E11+E12 | F13: =F14-F11+F12 | G13: =Drivers!$C$20 | H13: =Drivers!$C$20 | I13: =Drivers!$C$20 | J13: =Drivers!$C$20
A14: EBT | C14: 28.7 | D14: 32.5 | E14: 29.2 | F14: =Annual!C14-C14-D14-E14 | G14: =G11-G12+G13 | H14: =H11-H12+H13 | I14: =I11-I12+I13 | J14: =J11-J12+J13
A15: Tax | C15: 7.6 | D15: 7.3 | E15: 5.6 | F15: =Annual!C15-C15-D15-E15 | G15: =G14*Drivers!$C$14 | H15: =H14*Drivers!$C$14 | I15: =I14*Drivers!$C$14 | J15: =J14*Drivers!$C$14
A16: Other after-tax / NCI | C16: =C17-(C14-C15) | D16: =D17-(D14-D15) | E16: =E17-(E14-E15) | F16: =F17-(F14-F15) | G16: =Drivers!$C$21 | H16: =Drivers!$C$21 | I16: =Drivers!$C$21 | J16: =Drivers!$C$21
A17: NI | C17: 20.2 | D17: 24.2 | E17: 23.5 | F17: =Annual!C17-C17-D17-E17 | G17: =G14-G15+G16 | H17: =H14-H15+H16 | I17: =I14-I15+I16 | J17: =J14-J15+J16
A18: D&A (CF stmt) | C18: =C67 | D18: =D67-C67 | E18: =E67-D67 | F18: =Annual!C67-E67 | G18: =G6*Drivers!$C$12 | H18: =H6*Drivers!$C$12 | I18: =I6*Drivers!$C$12 | J18: =J6*Drivers!$C$12
A19: EBITDA | C19: =C11+C18 | D19: =D11+D18 | E19: =E11+E18 | F19: =F11+F18 | G19: =G11+G18 | H19: =H11+H18 | I19: =I11+I18 | J19: =J11+J18
A21: Balance sheet
A22: Cash | G22: =G59 | H22: =H59 | I22: =I59 | J22: =J59
A23: AR | G23: =G6*Drivers!$C$15/91.25 | H23: =H6*Drivers!$C$15/91.25 | I23: =I6*Drivers!$C$15/91.25 | J23: =J6*Drivers!$C$15/91.25
A24: Inventory | G24: =G7*Drivers!$C$16/91.25 | H24: =H7*Drivers!$C$16/91.25 | I24: =I7*Drivers!$C$16/91.25 | J24: =J7*Drivers!$C$16/91.25
A25: Other CA | G25: =Annual!C25 | H25: =G25 | I25: =H25 | J25: =I25
A26: Total CA | G26: =G22+G23+G24+G25 | H26: =H22+H23+H24+H25 | I26: =I22+I23+I24+I25 | J26: =J22+J23+J24+J25
A27: PP&E | G27: =Annual!C27-G52-G18 | H27: =G27-H52-H18 | I27: =H27-I52-I18 | J27: =I27-J52-J18
A28: Goodwill | G28: =Annual!C28 | H28: =G28 | I28: =H28 | J28: =I28
A29: Intangibles | G29: =Annual!C29 | H29: =G29 | I29: =H29 | J29: =I29
A30: Other NCA | G30: =Annual!C30 | H30: =G30 | I30: =H30 | J30: =I30
A31: Total assets | G31: =G26+G27+G28+G29+G30 | H31: =H26+H27+H28+H29+H30 | I31: =I26+I27+I28+I29+I30 | J31: =J26+J27+J28+J29+J30
A32: AP | G32: =G7*Drivers!$C$17/91.25 | H32: =H7*Drivers!$C$17/91.25 | I32: =I7*Drivers!$C$17/91.25 | J32: =J7*Drivers!$C$17/91.25
A33: ST debt | G33: =Annual!C33 | H33: =G33 | I33: =H33 | J33: =I33
A34: Current LTD | G34: =Annual!C34 | H34: =G34 | I34: =H34 | J34: =I34
A35: Other CL | G35: =Annual!C35 | H35: =G35 | I35: =H35 | J35: =I35
A36: Total CL | G36: =G32+G33+G34+G35 | H36: =H32+H33+H34+H35 | I36: =I32+I33+I34+I35 | J36: =J32+J33+J34+J35
A37: LT debt | G37: =Annual!C37 | H37: =G37 | I37: =H37 | J37: =I37
A38: Other NCL | G38: =Annual!C38 | H38: =G38 | I38: =H38 | J38: =I38
A39: Total liabilities | G39: =G44-G40-G41-G42 | H39: =H44-H40-H41-H42 | I39: =I44-I40-I41-I42 | J39: =J44-J40-J41-J42
A40: Redeemable NCI | G40: =Annual!C40 | H40: =G40 | I40: =H40 | J40: =I40
A41: Equity | G41: =Annual!C41+G17+G55 | H41: =G41+H17+H55 | I41: =H41+I17+I55 | J41: =I41+J17+J55
A42: NCI | G42: =Annual!C42 | H42: =G42 | I42: =H42 | J42: =I42
...

Sheet Annual
A1: MLKN annual model ($m)
C2: FY26 | D2: FY27 | E2: FY28E | F2: FY29E | G2: FY30E | H2: FY31E
C3: A | E3: E | F3: E | G3: E | H3: E
A5: P&L
A6: Rev | C6: 3841.7 | D6: =SUM(Quarterly!G6:J6) | E6: =D6*(1+Drivers!E8) | F6: =E6*(1+Drivers!F8) | G6: =F6*(1+Drivers!G8) | H6: =G6*(1+Drivers!H8)
A7: COGS | C7: 2352.9 | D7: =SUM(Quarterly!G7:J7) | E7: =E6*(1-Drivers!$C$9) | F7: =F6*(1-Drivers!$C$9) | G7: =G6*(1-Drivers!$C$9) | H7: =H6*(1-Drivers!$C$9)
A8: GP | C8: =C6-C7 | D8: =D6-D7 | E8: =E6-E7 | F8: =F6-F7 | G8: =G6-G7 | H8: =H6-H7
A9: SG&A | C9: 1178.3 | D9: =SUM(Quarterly!G9:J9) | E9: =E6*Drivers!$C$10 | F9: =F6*Drivers!$C$10 | G9: =G6*Drivers!$C$10 | H9: =H6*Drivers!$C$10
A10: Other opex | C10: =C8-C9-C11 | D10: =D8-D9-D11 | E10: =E6*Drivers!$C$11 | F10: =F6*Drivers!$C$11 | G10: =G6*Drivers!$C$11 | H10: =H6*Drivers!$C$11
A11: EBIT | C11: 198.3 | D11: =SUM(Quarterly!G11:J11) | E11: =E8-E9-E10 | F11: =F8-F9-F10 | G11: =G8-G9-G10 | H11: =H8-H9-H10
A12: Int exp, net | C12: 69.9 | D12: =SUM(Quarterly!G12:J12) | E12: =Drivers!$C$19 | F12: =Drivers!$C$19 | G12: =Drivers!$C$19 | H12: =Drivers!$C$19
A13: Other non-op | C13: =C14-C11+C12 | D13: =D14-D11+D12 | E13: 3.8 | F13: =Drivers!$C$20*4 | G13: =Drivers!$C$20*4 | H13: =Drivers!$C$20*4
A14: EBT | C14: 128.2 | D14: =SUM(Quarterly!G14:J14) | E14: =E11-E12+E13 | F14: =F11-F12+F13 | G14: =G11-G12+G13 | H14: =H11-H12+H13
A15: Tax | C15: 32.4 | D15: =SUM(Quarterly!G15:J15) | E15: =E14*Drivers!$C$14 | F15: =F14*Drivers!$C$14 | G15: =G14*Drivers!$C$14 | H15: =H14*Drivers!$C$14
A16: Other after-tax / NCI | C16: =C17-(C14-C15) | D16: =D17-(D14-D15) | E16: =Drivers!$C$21*4 | F16: =Drivers!$C$21*4 | G16: =Drivers!$C$21*4 | H16: =Drivers!$C$21*4
A17: NI | C17: 91.5 | D17: =SUM(Quarterly!G17:J17) | E17: =E14-E15+E16 | F17: =F14-F15+F16 | G17: =G14-G15+G16 | H17: =H14-H15+H16
A18: D&A (CF stmt) | C18: =C67 | D18: =SUM(Quarterly!G18:J18) | E18: =E6*Drivers!$C$12 | F18: =F6*Drivers!$C$12 | G18: =G6*Drivers!$C$12 | H18: =H6*Drivers!$C$12
A19: EBITDA | C19: =C11+C18 | D19: =D11+D18 | E19: =E11+E18 | F19: =F11+F18 | G19: =G11+G18 | H19: =H11+H18
A21: Balance sheet
A22: Cash | C22: 167.7 | E22: =E59 | F22: =F59 | G22: =G59 | H22: =H59
A23: AR | C23: 357.4 | E23: =E6*Drivers!$C$15/365 | F23: =F6*Drivers!$C$15/365 | G23: =G6*Drivers!$C$15/365 | H23: =H6*Drivers!$C$15/365
A24: Inventory | C24: 488.4 | E24: =E7*Drivers!$C$16/365 | F24: =F7*Drivers!$C$16/365 | G24: =G7*Drivers!$C$16/365 | H24: =H7*Drivers!$C$16/365
A25: Other CA | C25: =C26-C22-C23-C24 | E25: =Quarterly!J25 | F25: =E25 | G25: =F25 | H25: =G25
A26: Total CA | C26: 1137.2 | E26: =E22+E23+E24+E25 | F26: =F22+F23+F24+F25 | G26: =G22+G23+G24+G25 | H26: =H22+H23+H24+H25
A27: PP&E | C27: 511.3 | E27: =Quarterly!J27-E52-E18 | F27: =E27-F52-F18 | G27: =F27-G52-G18 | H27: =G27-H52-H18
A28: Goodwill | C28: 1161.3 | E28: =Quarterly!J28 | F28: =E28 | G28: =F28 | H28: =G28
A29: Intangibles | C29: 214 | E29: =Quarterly!J29 | F29: =E29 | G29: =F29 | H29: =G29
A30: Other NCA | C30: =C31-C26-C27-C28-C29 | E30: =Quarterly!J30 | F30: =E30 | G30: =F30 | H30: =G30
A31: Total assets | C31: 4000.5 | E31: =E26+E27+E28+E29+E30 | F31: =F26+F27+F28+F29+F30 | G31: =G26+G27+G28+G29+G30 | H31: =H26+H27+H28+H29+H30
A32: AP | C32: 279.1 | E32: =E7*Drivers!$C$17/365 | F32: =F7*Drivers!$C$17/365 | G32: =G7*Drivers!$C$17/365 | H32: =H7*Drivers!$C$17/365
A33: ST debt | C33: 0 | E33: =Quarterly!J33 | F33: =E33 | G33: =F33 | H33: =G33
A34: Current LTD | C34: 25.1 | E34: =Quarterly!J34 | F34: =E34 | G34: =F34 | H34: =G34
A35: Other CL | C35: =C36-C32-C33-C34 | E35: =Quarterly!J35 | F35: =E35 | G35: =F35 | H35: =G35
A36: Total CL | C36: 721.1 | E36: =E32+E33+E34+E35 | F36: =F32+F33+F34+F35 | G36: =G32+G33+G34+G35 | H36: =H32+H33+H34+H35
A37: LT debt | C37: 1260.6 | E37: =Quarterly!J37 | F37: =E37 | G37: =F37 | H37: =G37
A38: Other NCL | C38: =C44-C36-C37-C40-C41-C42 | E38: =Quarterly!J38 | F38: =E38 | G38: =F38 | H38: =G38
A39: Total liabilities | C39: =C44-C40-C41-C42 | E39: =E44-E40-E41-E42 | F39: =F44-F40-F41-F42 | G39: =G44-G40-G41-G42 | H39: =H44-H40-H41-H42
A40: Redeemable NCI | C40: 63.3 | E40: =Quarterly!J40 | F40: =E40 | G40: =F40 | H40: =G40
A41: Equity | C41: 1342.6 | E41: =Quarterly!J41+E17+E55 | F41: =E41+F17+F55 | G41: =F41+G17+G55 | H41: =G41+H17+H55
A42: NCI | C42: 0 | E42: =Quarterly!J42 | F42: =E42 | G42: =F42 | H42: =G42
...

Sheet Valuation
A1: MLKN DCF ($m)
C2: Q1 FY27 | D2: Q2 FY27 | E2: Q3 FY27 | F2: Q4 FY27 | H2: FY28E | I2: FY29E | J2: FY30E | K2: FY31E
C3: =IF(1<=Drivers!$C$4,"A","E") | D3: =IF(2<=Drivers!$C$4,"A","E") | E3: =IF(3<=Drivers!$C$4,"A","E") | F3: =IF(4<=Drivers!$C$4,"A","E") | H3: E | I3: E | J3: E | K3: E
A5: Fiscal quarter | C5: 1 | D5: 2 | E5: 3 | F5: 4
A6: EBIT | C6: =Quarterly!G11 | D6: =Quarterly!H11 | E6: =Quarterly!I11 | F6: =Quarterly!J11 | H6: =Annual!E11 | I6: =Annual!F11 | J6: =Annual!G11 | K6: =Annual!H11
A7: Tax on EBIT | C7: =-C6*Drivers!$C$14 | D7: =-D6*Drivers!$C$14 | E7: =-E6*Drivers!$C$14 | F7: =-F6*Drivers!$C$14 | H7: =-H6*Drivers!$C$14 | I7: =-I6*Drivers!$C$14 | J7: =-J6*Drivers!$C$14 | K7: =-K6*Drivers!$C$14
A8: NOPAT | C8: =C6+C7 | D8: =D6+D7 | E8: =E6+E7 | F8: =F6+F7 | H8: =H6+H7 | I8: =I6+I7 | J8: =J6+J7 | K8: =K6+K7
A9: Depreciation and amortization | C9: =Quarterly!G18 | D9: =Quarterly!H18 | E9: =Quarterly!I18 | F9: =Quarterly!J18 | H9: =Annual!E18 | I9: =Annual!F18 | J9: =Annual!G18 | K9: =Annual!H18
A10: Capital expenditures | C10: =Quarterly!G52 | D10: =Quarterly!H52 | E10: =Quarterly!I52 | F10: =Quarterly!J52 | H10: =Annual!E52 | I10: =Annual!F52 | J10: =Annual!G52 | K10: =Annual!H52
A11: Working capital and other | C11: =Quarterly!G50 | D11: =Quarterly!H50 | E11: =Quarterly!I50 | F11: =Quarterly!J50 | H11: =Annual!E50 | I11: =Annual!F50 | J11: =Annual!G50 | K11: =Annual!H50
A12: Unlevered free cash flow | C12: =C8+C9+C10+C11 | D12: =D8+D9+D10+D11 | E12: =E8+E9+E10+E11 | F12: =F8+F9+F10+F11 | H12: =H8+H9+H10+H11 | I12: =I8+I9+I10+I11 | J12: =J8+J9+J10+J11 | K12: =K8+K9+K10+K11
A13: Discount period (years from the balance sheet date) | H13: =C19+1 | I13: =C19+2 | J13: =C19+3 | K13: =C19+4
A14: Discount factor | H14: =1/(1+Drivers!$C$25)^H13 | I14: =1/(1+Drivers!$C$25)^I13 | J14: =1/(1+Drivers!$C$25)^J13 | K14: =1/(1+Drivers!$C$25)^K13
A15: PV of unlevered free cash flow | H15: =H12*H14 | I15: =I12*I14 | J15: =J12*J14 | K15: =K12*K14
A17: Revenue, last four reported quarters | C17: =SUM(Quarterly!C6:F6)
A18: EBITDA, last four reported quarters | C18: =SUM(Quarterly!C19:F19)
A19: Rest of the current fiscal year (years) | C19: =(4-Drivers!$C$4)/4
A20: Unlevered free cash flow, rest of the current fiscal year | C20: =SUMPRODUCT((C5:F5>Drivers!$C$4)*C12:F12)
A21: Discount factor, rest of the current fiscal year | C21: =1/(1+Drivers!$C$25)^C19
A22: PV, rest of the current fiscal year | C22: =C20*C21
A23: Terminal value (Gordon growth, end of last forecast year) | C23: =K12*(1+Drivers!$C$26)/(Drivers!$C$25-Drivers!$C$26)
A24: PV of terminal value | C24: =C23*K14
A25: Enterprise value | C25: =C22+SUM(H15:K15)+C24
A26: Less: cash and cash equivalents (latest reported balance sheet) | C26: =Annual!C22
A27: Short-term borrowings (latest reported balance sheet) | C27: =Annual!C33
A28: Current portion of long-term debt (latest reported balance sheet) | C28: =Annual!C34
A29: Long-term debt (latest reported balance sheet) | C29: =Annual!C37
A30: Net debt | C30: =C27+C28+C29-C26
A31: Non-controlling interests, incl. redeemable (latest reported balance sheet) | C31: =Annual!C42+Annual!C40
A32: Equity value | C32: =C25-C30-C31
A33: Shares outstanding | C33: =Drivers!$C$5
A34: Equity value per share ($) | C34: =C32/C33
A35: Enterprise value / EBITDA, last four reported quarters (x) | C35: =C25/C18

Sheet Scratch
