Workbook

Sheet Valuations & Forecasting
A1: Consolidated Statements of Income - USD ($) shares in Millions, $ in Millions | B1: 12 Months Ended | Q1: 3 Months Ended
B2: May 31, 2015 | C2: May 31, 2016 | D2: May 31, 2017 | E2: May 31, 2018 | F2: May 31, 2019 | G2: May 31, 2020 | H2: May 31, 2021 | I2: May 31, 2022 | J2: May 31, 2023 | K2: May 31, 2024 E | L2: May 31, 2024 (Audited) | N2: May 31, 2025 E | O2: May 31, 2026 E | Q2: Aug. 31, 2020 | R2: Nov. 30, 2020 | S2: Feb. 28, 2021 | T2: May. 31, 2021 | V2: Aug. 31, 2021 | W2: Nov. 30, 2021 | X2: Feb. 28, 2022 | Y2: May. 31, 2022 | AA2: Aug. 31, 2022 | AB2: Nov. 30, 2022 | AC2: Feb. 28, 2023 | AD2: May. 31, 2023 | AF2: Aug. 31, 2023 | AG2: Nov. 30, 2023 | AH2: Feb. 29, 2024 | AI2: May. 31, 2024 E | AJ2: May. 31, 2024 | AM2: Aug. 31, 2024 E | AN2: Nov. 30, 2024 E | AO2: Feb. 29, 2025 E | AP2: May. 31, 2025 E
A3: Income Statement [Abstract]
A4: North America
A5: Footwear | E5: 9322 | F5: 10045 | G5: 9329 | H5: 11644 | I5: 12228 | J5: =AA5+AB5+AC5+AD5 -> 14897 | K5: =AF5+AG5+AH5+AI5 -> 14940 | L5: =SUM(AF5:AH5)+AJ5 -> 14537 | M5: =L5/K5-1 -> -0.026974565 | N5: =SUM(AM5:AP5) -> 15550 | O5: 16700 | Q5: 2957 | R5: 2512 | S5: 2382 | T5: 3793 | V5: 3264 | W5: 2852 | X5: 2532 | Y5: 3580 | AA5: 3805 | AB5: 3963 | AC5: 3322 | AD5: 3807 | AF5: 3733 | AG5: 3757 | AH5: 3460 | AI5: 3990 | AJ5: 3587 | AK5: =AJ5/AI5-1 -> -0.10100251 | AM5: 3900 | AN5: 3900 | AO5: 3600 | AP5: 4150
A6: Apparel | E6: 4938 | F6: 5260 | G6: 4639 | H6: 5028 | I6: 5492 | J6: =AA6+AB6+AC6+AD6 -> 5947 | K6: =AF6+AG6+AH6+AI6 -> 5925 | L6: =SUM(AF6:AH6)+AJ6 -> 5953 | M6: =L6/K6-1 -> 0.0047257384 | N6: =SUM(AM6:AP6) -> 6015 | O6: 6200 | Q6: 1125 | R6: 1368 | S6: 1087 | T6: 1448 | V6: 1430 | W6: 1480 | X6: 1207 | Y6: 1375 | AA6: 1494 | AB6: 1685 | AC6: 1419 | AD6: 1349 | AF6: 1479 | AG6: 1668 | AH6: 1408 | AI6: 1370 | AJ6: 1398 | AK6: =AJ6/AI6-1 -> 0.020437956 | AM6: 1500 | AN6: 1700 | AO6: 1420 | AP6: 1395
A7: Equipment | E7: 595 | F7: 597 | G7: 516 | H7: 507 | I7: 633 | J7: =AA7+AB7+AC7+AD7 -> 764 | K7: =AF7+AG7+AH7+AI7 -> 843 | L7: =SUM(AF7:AH7)+AJ7 -> 906 | M7: =L7/K7-1 -> 0.074733096 | N7: =SUM(AM7:AP7) -> 940 | O7: 1030 | Q7: 143 | R7: 126 | S7: 95 | T7: 143 | V7: 185 | W7: 145 | X7: 143 | Y7: 160 | AA7: 211 | AB7: 182 | AC7: 172 | AD7: 199 | AF7: 211 | AG7: 200 | AH7: 202 | AI7: 230 | AJ7: 293 | AK7: =AJ7/AI7-1 -> 0.27391304 | AM7: 220 | AN7: 220 | AO7: 240 | AP7: 260
A8: Total | B8: =B5+B6+B7 -> 0 | C8: =C5+C6+C7 -> 0 | D8: =D5+D6+D7 -> 0 | E8: =E5+E6+E7 -> 14855 | F8: =F5+F6+F7 -> 15902 | G8: =G5+G6+G7 -> 14484 | H8: =H5+H6+H7 -> 17179 | I8: =I5+I6+I7 -> 18353 | ... L8: =L5+L6+L7 -> 21396 | M8: =L8/K8-1 -> -0.014372582 | N8: =SUM(AM8:AP8) -> 22505 | O8: =O5+O6+O7 -> 23930 | Q8: =Q5+Q6+Q7 -> 4225 | R8: =R5+R6+R7 -> 4006 | S8: =S5+S6+S7 -> 3564 | T8: =T5+T6+T7 -> 5384 | V8: =V5+V6+V7 -> 4879 | W8: =W5+W6+W7 -> 4477 | X8: =X5+X6+X7 -> 3882 | Y8: =Y5+Y6+Y7 -> 5115 | AA8: =AA5+AA6+AA7 -> 5510 | AB8: =AB5+AB6+AB7 -> 5830 | AC8: =AC5+AC6+AC7 -> 4913 | AD8: =AD5+AD6+AD7 -> 5355 | AF8: =AF5+AF6+AF7 -> 5423 | AG8: =AG5+AG6+AG7 -> 5625 | AH8: =AH5+AH6+AH7 -> 5070 | AI8: =AI5+AI6+AI7 -> 5590 | AJ8: =AJ5+AJ6+AJ7 -> 5278 | AK8: =AJ8/AI8-1 -> -0.055813953 | AM8: =AM5+AM6+AM7 -> 5620 | AN8: =AN5+AN6+AN7 -> 5820 | AO8: =AO5+AO6+AO7 -> 5260 | AP8: =AP5+AP6+AP7 -> 5805
A9: Europe, Middle East & Africa
A10: Footwear | E10: 5875 | F10: 6293 | G10: 5892 | H10: 6970 | I10: 7388 | J10: =AA10+AB10+AC10+AD10 -> 8260 | K10: =AF10+AG10+AH10+AI10 -> 8606 | L10: =SUM(AF10:AH10)+AJ10 -> 8473 | M10: =L10/K10-1 -> -0.015454334 | N10: =SUM(AM10:AP10) -> 9100 | O10: 9500 | Q10: 1802 | R10: 1731 | S10: 1606 | T10: 1831 | V10: 1983 | W10: 1806 | X10: 1569 | Y10: 2030 | AA10: 2012 | AB10: 2063 | AC10: 2011 | AD10: 2174 | AF10: 2260 | AG10: 2186 | AH10: 1960 | AI10: 2200 | AJ10: 2067 | AK10: =AJ10/AI10-1 -> -0.060454545 | AM10: 2500 | AN10: 2300 | AO10: 2050 | AP10: 2250
A11: Apparel | E11: 2940 | F11: 3087 | G11: 3053 | H11: 3996 | I11: 4527 | J11: =AA11+AB11+AC11+AD11 -> 4566 | K11: =AF11+AG11+AH11+AI11 -> 4266 | L11: =SUM(AF11:AH11)+AJ11 -> 4380 | M11: =L11/K11-1 -> 0.026722925 | N11: =SUM(AM11:AP11) -> 4305 | O11: 4500 | Q11: 971 | R11: 1104 | S11: 898 | T11: 1023 | V11: 1159 | W11: 1202 | X11: 1083 | Y11: 1083 | AA11: 1153 | AB11: 1281 | AC11: 1094 | AD11: 1038 | AF11: 1137 | AG11: 1200 | AH11: 994 | AI11: 935 | AJ11: 1049 | AK11: =AJ11/AI11-1 -> 0.12192513 | AM11: 1140 | AN11: 1220 | AO11: 1000 | AP11: 945
A12: Equipment | E12: 427 | F12: 432 | G12: 402 | H12: 490 | I12: 564 | J12: =AA12+AB12+AC12+AD12 -> 592 | K12: =AF12+AG12+AH12+AI12 -> 753 | L12: =SUM(AF12:AH12)+AJ12 -> 754 | M12: =L12/K12-1 -> 0.0013280212 | N12: =SUM(AM12:AP12) -> 944 | O12: 1050 | Q12: 137 | R12: 123 | S12: 105 | T12: 125 | V12: 165 | W12: 134 | X12: 127 | Y12: 138 | AA12: 168 | AB12: 145 | AC12: 141 | AD12: 138 | AF12: 213 | AG12: 181 | AH12: 184 | AI12: 175 | AJ12: 176 | AK12: =AJ12/AI12-1 -> 0.0057142857 | AM12: 265 | AN12: 224 | AO12: 235 | AP12: 220
A13: Total | B13: =B10+B11+B12 -> 0 | C13: =C10+C11+C12 -> 0 | D13: =D10+D11+D12 -> 0 | E13: =E10+E11+E12 -> 9242 | F13: =F10+F11+F12 -> 9812 | G13: =G10+G11+G12 -> 9347 | H13: =H10+H11+H12 -> 11456 | I13: =I10+I11+I12 -> 12479 | ... L13: =L10+L11+L12 -> 13607 | M13: =L13/K13-1 -> -0.0013211009 | N13: =SUM(AM13:AP13) -> 14349 | O13: =O10+O11+O12 -> 15050 | Q13: =Q10+Q11+Q12 -> 2910 | R13: =R10+R11+R12 -> 2958 | S13: =S10+S11+S12 -> 2609 | T13: 2979 | V13: =V10+V11+V12 -> 3307 | W13: =W10+W11+W12 -> 3142 | X13: =X10+X11+X12 -> 2779 | Y13: =Y10+Y11+Y12 -> 3251 | AA13: =AA10+AA11+AA12 -> 3333 | AB13: =AB10+AB11+AB12 -> 3489 | AC13: =AC10+AC11+AC12 -> 3246 | AD13: =AD10+AD11+AD12 -> 3350 | AF13: =AF10+AF11+AF12 -> 3610 | AG13: =AG10+AG11+AG12 -> 3567 | AH13: =AH10+AH11+AH12 -> 3138 | AI13: =AI10+AI11+AI12 -> 3310 | AJ13: =AJ10+AJ11+AJ12 -> 3292 | AK13: =AJ13/AI13-1 -> -0.0054380665 | AM13: =AM10+AM11+AM12 -> 3905 | AN13: =AN10+AN11+AN12 -> 3744 | AO13: =AO10+AO11+AO12 -> 3285 | AP13: =AP10+AP11+AP12 -> 3415
A14: Greater China
A15: Footwear | E15: 3496 | F15: 4262 | G15: 4635 | H15: 5748 | I15: 5416 | J15: =AA15+AB15+AC15+AD15 -> 5435 | K15: =AF15+AG15+AH15+AI15 -> 5595 | L15: =SUM(AF15:AH15)+AJ15 -> 5552 | M15: =L15/K15-1 -> -0.0076854334 | N15: =SUM(AM15:AP15) -> 5800 | O15: 6000 | Q15: 1251 | R15: 1567 | S15: 1614 | T15: 1316 | V15: 1449 | W15: 1235 | X15: 1554 | Y15: 1178 | AA15: 1233 | AB15: 1370 | AC15: 1496 | AD15: 1336 | AF15: 1287 | AG15: 1361 | AH15: 1547 | AI15: 1400 | AJ15: 1357 | AK15: =AJ15/AI15-1 -> -0.030714286 | AM15: 1350 | AN15: 1370 | AO15: 1600 | AP15: 1480
A16: Apparel | E16: 1508 | F16: 1808 | G16: 1896 | H16: 2347 | I16: 1938 | J16: =AA16+AB16+AC16+AD16 -> 1666 | K16: =AF16+AG16+AH16+AI16 -> 1848 | L16: =SUM(AF16:AH16)+AJ16 -> 1828 | M16: =L16/K16-1 -> -0.010822511 | N16: =SUM(AM16:AP16) -> 2090 | O16: 2300 | Q16: 478 | R16: 681 | S16: 616 | T16: 572 | V16: 476 | W16: 564 | X16: 548 | Y16: 350 | AA16: 374 | AB16: 393 | AC16: 461 | AD16: 438 | AF16: 401 | AG16: 469 | AH16: 498 | AI16: 480 | AJ16: 460 | AK16: =AJ16/AI16-1 -> -0.041666667 | AM16: 430 | AN16: 560 | AO16: 550 | AP16: 550
A17: Equipment | E17: 130 | F17: 138 | G17: 148 | H17: 195 | I17: 193 | J17: =AA17+AB17+AC17+AD17 -> 147 | K17: =AF17+AG17+AH17+AI17 -> 156 | L17: =SUM(AF17:AH17)+AJ17 -> 165 | M17: =L17/K17-1 -> 0.057692308 | N17: =SUM(AM17:AP17) -> 170 | O17: 190 | Q17: 51 | R17: 50 | S17: 49 | T17: 45 | V17: 57 | W17: 45 | X17: 58 | Y17: 33 | AA17: 49 | AB17: 25 | AC17: 37 | AD17: 36 | AF17: 47 | AG17: 33 | AH17: 39 | AI17: 37 | AJ17: 46 | AK17: =AJ17/AI17-1 -> 0.24324324 | AM17: 48 | AN17: 42 | AO17: 41 | AP17: 39
A18: Total | B18: =B15+B16+B17 -> 0 | C18: =C15+C16+C17 -> 0 | D18: =D15+D16+D17 -> 0 | E18: =E15+E16+E17 -> 5134 | F18: =F15+F16+F17 -> 6208 | G18: =G15+G16+G17 -> 6679 | H18: =H15+H16+H17 -> 8290 | I18: =I15+I16+I17 -> 7547 | ... L18: =L15+L16+L17 -> 7545 | M18: =L18/K18-1 -> -0.0071061982 | N18: =SUM(AM18:AP18) -> 8060 | O18: =O15+O16+O17 -> 8490 | Q18: =Q15+Q16+Q17 -> 1780 | R18: =R15+R16+R17 -> 2298 | S18: =S15+S16+S17 -> 2279 | T18: =T15+T16+T17 -> 1933 | V18: =V15+V16+V17 -> 1982 | W18: =W15+W16+W17 -> 1844 | X18: =X15+X16+X17 -> 2160 | Y18: =Y15+Y16+Y17 -> 1561 | AA18: =AA15+AA16+AA17 -> 1656 | AB18: =AB15+AB16+AB17 -> 1788 | AC18: =AC15+AC16+AC17 -> 1994 | AD18: =AD15+AD16+AD17 -> 1810 | AF18: =AF15+AF16+AF17 -> 1735 | AG18: =AG15+AG16+AG17 -> 1863 | AH18: =AH15+AH16+AH17 -> 2084 | AI18: =AI15+AI16+AI17 -> 1917 | AJ18: =AJ15+AJ16+AJ17 -> 1863 | AK18: =AJ18/AI18-1 -> -0.028169014 | AM18: =AM15+AM16+AM17 -> 1828 | AN18: =AN15+AN16+AN17 -> 1972 | AO18: =AO15+AO16+AO17 -> 2191 | AP18: =AP15+AP16+AP17 -> 2069
A19: Asian Pacific & Latin America
A20: Footwear | E20: 3575 | F20: 3622 | G20: 3449 | H20: 3659 | I20: 4111 | J20: =AA20+AB20+AC20+AD20 -> 4543 | K20: =AF20+AG20+AH20+AI20 -> 4939 | L20: =SUM(AF20:AH20)+AJ20 -> 4865 | M20: =L20/K20-1 -> -0.01498279 | N20: =SUM(AM20:AP20) -> 5440 | O20: 5900 | Q20: 758 | R20: 991 | S20: 903 | T20: 1007 | V20: 1022 | W20: 887 | X20: 1005 | Y20: 1197 | AA20: 1064 | AB20: 1108 | AC20: 1141 | AD20: 1230 | AF20: 1141 | AG20: 1303 | AH20: 1195 | AI20: 1300 | AJ20: 1226 | AK20: =AJ20/AI20-1 -> -0.056923077 | AM20: 1230 | AN20: 1560 | AO20: 1260 | AP20: 1390
A21: Apparel | E21: 1347 | F21: 1395 | G21: 1365 | H21: 1494 | I21: 1610 | J21: =AA21+AB21+AC21+AD21 -> 1664 | K21: =AF21+AG21+AH21+AI21 -> 1593 | L21: =SUM(AF21:AH21)+AJ21 -> 1614 | M21: =L21/K21-1 -> 0.013182674 | N21: =SUM(AM21:AP21) -> 1610 | O21: 1730 | Q21: 301 | R21: 432 | S21: 365 | T21: 396 | V21: 385 | W21: 402 | X21: 394 | Y21: 429 | AA21: 413 | AB21: 435 | AC21: 407 | AD21: 409 | AF21: 371 | AG21: 437 | AH21: 390 | AI21: 395 | AJ21: 416 | AK21: =AJ21/AI21-1 -> 0.053164557 | AM21: 370 | AN21: 440 | AO21: 400 | AP21: 400
A22: Equipment | E22: 244 | F22: 237 | G22: 214 | H22: 190 | I22: 234 | J22: =AA22+AB22+AC22+AD22 -> 224 | K22: =AF22+AG22+AH22+AI22 -> 247 | L22: =SUM(AF22:AH22)+AJ22 -> 250 | M22: =L22/K22-1 -> 0.012145749 | N22: =SUM(AM22:AP22) -> 276 | O22: 290 | Q22: 40 | R22: 48 | S22: 47 | T22: 55 | V22: 58 | W22: 58 | X22: 62 | Y22: 56 | AA22: 58 | AB22: 56 | AC22: 53 | AD22: 57 | AF22: 60 | AG22: 65 | AH22: 62 | AI22: 60 | AJ22: 63 | AK22: =AJ22/AI22-1 -> 0.05 | AM22: 62 | AN22: 77 | AO22: 73 | AP22: 64
A23: Total | B23: =B20+B21+B22 -> 0 | C23: =C20+C21+C22 -> 0 | D23: =D20+D21+D22 -> 0 | E23: =E20+E21+E22 -> 5166 | F23: =F20+F21+F22 -> 5254 | G23: =G20+G21+G22 -> 5028 | H23: =H20+H21+H22 -> 5343 | I23: =I20+I21+I22 -> 5955 | ... L23: =L20+L21+L22 -> 6729 | M23: =L23/K23-1 -> -0.0073757191 | N23: =SUM(AM23:AP23) -> 7326 | O23: =O20+O21+O22 -> 7920 | Q23: =Q20+Q21+Q22 -> 1099 | R23: =R20+R21+R22 -> 1471 | S23: =S20+S21+S22 -> 1315 | T23: =T20+T21+T22 -> 1458 | V23: =V20+V21+V22 -> 1465 | W23: =W20+W21+W22 -> 1347 | X23: =X20+X21+X22 -> 1461 | Y23: =Y20+Y21+Y22 -> 1682 | AA23: =AA20+AA21+AA22 -> 1535 | AB23: =AB20+AB21+AB22 -> 1599 | AC23: =AC20+AC21+AC22 -> 1601 | AD23: =AD20+AD21+AD22 -> 1696 | AF23: =AF20+AF21+AF22 -> 1572 | AG23: =AG20+AG21+AG22 -> 1805 | AH23: =AH20+AH21+AH22 -> 1647 | AI23: =AI20+AI21+AI22 -> 1755 | AJ23: =AJ20+AJ21+AJ22 -> 1705 | AK23: =AJ23/AI23-1 -> -0.028490028 | AM23: =AM20+AM21+AM22 -> 1662 | AN23: =AN20+AN21+AN22 -> 2077 | AO23: =AO20+AO21+AO22 -> 1733 | AP23: =AP20+AP21+AP22 -> 1854
A24: Global Brand Division2 | E24: 88 | F24: 42 | G24: 30 | H24: 25 | I24: 102 | J24: =AA24+AB24+AC24+AD24 -> 58 | K24: =AF24+AG24+AH24+AI24 -> 45 | L24: =SUM(AF24:AH24)+AJ24 -> 45 | M24: =L24/K24-1 -> 0 | N24: =SUM(AM24:AP24) -> 56 | O24: 60 | Q24: 4 | R24: 8 | S24: 6 | T24: 7 | V24: 7 | W24: 6 | X24: 41 | Y24: 48 | AA24: 14 | AB24: 18 | AC24: 12 | AD24: 14 | AF24: 13 | AG24: 12 | AH24: 9 | AI24: 11 | AJ24: 11 | AK24: =AJ24/AI24-1 -> 0 | AM24: 14 | AN24: 15 | AO24: 11 | AP24: 16
A25: Total Nike Brand | B25: =B24+B23+B18+B13+B8 -> 0 | C25: =C24+C23+C18+C13+C8 -> 0 | D25: =D24+D23+D18+D13+D8 -> 0 | E25: =E24+E23+E18+E13+E8 -> 34485 | F25: =F24+F23+F18+F13+F8 -> 37218 | G25: =G24+G23+G18+G13+G8 -> 35568 | H25: =H24+H23+H18+H13+H8 -> 42293 | I25: =I24+I23+I18+I13+I8 -> 44436 | ... L25: =L24+L23+L18+L13+L8 -> 49322 | M25: =L25/K25-1 -> -0.0087225661 | N25: =SUM(AM25:AP25) -> 52296 | O25: =O24+O23+O18+O13+O8 -> 55450 | Q25: =Q24+Q23+Q18+Q13+Q8 -> 10018 | R25: =R24+R23+R18+R13+R8 -> 10741 | S25: =S24+S23+S18+S13+S8 -> 9773 | T25: =T24+T23+T18+T13+T8 -> 11761 | V25: =V24+V23+V18+V13+V8 -> 11640 | W25: =W24+W23+W18+W13+W8 -> 10816 | X25: =X24+X23+X18+X13+X8 -> 10323 | Y25: =Y24+Y23+Y18+Y13+Y8 -> 11657 | AA25: =AA24+AA23+AA18+AA13+AA8 -> 12048 | AB25: =AB24+AB23+AB18+AB13+AB8 -> 12724 | AC25: =AC24+AC23+AC18+AC13+AC8 -> 11766 | AD25: =AD24+AD23+AD18+AD13+AD8 -> 12225 | AF25: =AF24+AF23+AF18+AF13+AF8 -> 12353 | AG25: =AG24+AG23+AG18+AG13+AG8 -> 12872 | AH25: =AH24+AH23+AH18+AH13+AH8 -> 11948 | AI25: =AI24+AI23+AI18+AI13+AI8 -> 12583 | AJ25: =AJ24+AJ23+AJ18+AJ13+AJ8 -> 12149 | AK25: =AJ25/AI25-1 -> -0.03449098 | AM25: =AM24+AM23+AM18+AM13+AM8 -> 13029 | AN25: =AN24+AN23+AN18+AN13+AN8 -> 13628 | AO25: =AO24+AO23+AO18+AO13+AO8 -> 12480 | AP25: =AP24+AP23+AP18+AP13+AP8 -> 13159
A26: Converse | E26: 1886 | F26: 1906 | G26: 1846 | H26: 2205 | I26: 2346 | J26: =AA26+AB26+AC26+AD26 -> 2427 | K26: =AF26+AG26+AH26+AI26 -> 2102 | L26: =SUM(AF26:AH26)+AJ26 -> 2082 | M26: =L26/K26-1 -> -0.0095147479 | N26: =SUM(AM26:AP26) -> 2135 | O26: 2300 | Q26: 563 | R26: 476 | S26: 570 | T26: 596 | V26: 629 | W26: 557 | X26: 567 | Y26: 593 | AA26: 643 | AB26: 586 | AC26: 612 | AD26: 586 | AF26: 588 | AG26: 519 | AH26: 495 | AI26: 500 | AJ26: 480 | AK26: =AJ26/AI26-1 -> -0.04 | AM26: 590 | AN26: 525 | AO26: 510 | AP26: 510
A27: Corporate3 | E27: 26 | F27: -7 | G27: -11 | H27: 40 | I27: -72 | J27: =AA27+AB27+AC27+AD27 -> 27 | K27: =AF27+AG27+AH27+AI27 -> -29 | L27: =SUM(AF27:AH27)+AJ27 -> -42 | M27: =L27/K27-1 -> 0.44827586 | N27: =SUM(AM27:AP27) -> -2 | O27: 20 | Q27: 13 | R27: 26 | S27: 14 | T27: -13 | V27: -21 | W27: -16 | X27: -19 | Y27: -16 | AA27: -4 | AB27: 5 | AC27: 12 | AD27: 14 | AF27: -2 | AG27: -3 | AH27: -14 | AI27: -10 | AJ27: -23 | AK27: =AJ27/AI27-1 -> 1.3 | AM27: 1 | AN27: 2 | AO27: -2 | AP27: -3
A28: Total Nike Brand:
A29: Footwear | E29: =E5+E10+E15+E20 -> 22268 | F29: =F5+F10+F15+F20 -> 24222 | G29: =G5+G10+G15+G20 -> 23305 | H29: =H5+H10+H15+H20 -> 28021 | I29: =I5+I10+I15+I20 -> 29143 | J29: =J5+J10+J15+J20 -> 33135 | K29: =K5+K10+K15+K20 -> 34080 | L29: =SUM(AF29:AH29)+AJ29 -> 33427 | M29: =L29/K29-1 -> -0.019160798 | N29: =N5+N10+N15+N20 -> 35890 | O29: =O5+O10+O15+O20 -> 38100 | Q29: =Q5+Q10+Q15+Q20 -> 6768 | R29: =R5+R10+R15+R20 -> 6801 | S29: =S5+S10+S15+S20 -> 6505 | T29: =T5+T10+T15+T20 -> 7947 | V29: =V5+V10+V15+V20 -> 7718 | W29: =W5+W10+W15+W20 -> 6780 | X29: =X5+X10+X15+X20 -> 6660 | Y29: =Y5+Y10+Y15+Y20 -> 7985 | AA29: =AA5+AA10+AA15+AA20 -> 8114 | AB29: =AB5+AB10+AB15+AB20 -> 8504 | AC29: =AC5+AC10+AC15+AC20 -> 7970 | AD29: =AD5+AD10+AD15+AD20 -> 8547 | AF29: =AF5+AF10+AF15+AF20 -> 8421 | AG29: =AG5+AG10+AG15+AG20 -> 8607 | AH29: =AH5+AH10+AH15+AH20 -> 8162 | AI29: =AI5+AI10+AI15+AI20 -> 8890 | AJ29: =AJ5+AJ10+AJ15+AJ20 -> 8237 | AK29: =AJ29/AI29-1 -> -0.073453318 | AM29: =AM5+AM10+AM15+AM20 -> 8980 | AN29: =AN5+AN10+AN15+AN20 -> 9130 | AO29: =AO5+AO10+AO15+AO20 -> 8510 | AP29: =AP5+AP10+AP15+AP20 -> 9270
A30: Apparel | E30: =E6+E11+E16+E21 -> 10733 | F30: =F6+F11+F16+F21 -> 11550 | G30: =G6+G11+G16+G21 -> 10953 | H30: =H6+H11+H16+H21 -> 12865 | I30: =I6+I11+I16+I21 -> 13567 | J30: =J6+J11+J16+J21 -> 13843 | K30: =K6+K11+K16+K21 -> 13632 | L30: =SUM(AF30:AH30)+AJ30 -> 13775 | M30: =L30/K30-1 -> 0.010490023 | N30: =N6+N11+N16+N21 -> 14020 | O30: =O6+O11+O16+O21 -> 14730 | Q30: =Q6+Q11+Q16+Q21 -> 2875 | R30: =R6+R11+R16+R21 -> 3585 | S30: =S6+S11+S16+S21 -> 2966 | T30: =T6+T11+T16+T21 -> 3439 | V30: =V6+V11+V16+V21 -> 3450 | W30: =W6+W11+W16+W21 -> 3648 | X30: =X6+X11+X16+X21 -> 3232 | Y30: =Y6+Y11+Y16+Y21 -> 3237 | AA30: =AA6+AA11+AA16+AA21 -> 3434 | AB30: =AB6+AB11+AB16+AB21 -> 3794 | AC30: =AC6+AC11+AC16+AC21 -> 3381 | AD30: =AD6+AD11+AD16+AD21 -> 3234 | AF30: =AF6+AF11+AF16+AF21 -> 3388 | AG30: =AG6+AG11+AG16+AG21 -> 3774 | AH30: =AH6+AH11+AH16+AH21 -> 3290 | AI30: =AI6+AI11+AI16+AI21 -> 3180 | AJ30: =AJ6+AJ11+AJ16+AJ21 -> 3323 | AK30: =AJ30/AI30-1 -> 0.044968553 | AM30: =AM6+AM11+AM16+AM21 -> 3440 | AN30: =AN6+AN11+AN16+AN21 -> 3920 | AO30: =AO6+AO11+AO16+AO21 -> 3370 | AP30: =AP6+AP11+AP16+AP21 -> 3290
A31: Equipment | E31: =E7+E12+E17+E22 -> 1396 | F31: =F7+F12+F17+F22 -> 1404 | G31: =G7+G12+G17+G22 -> 1280 | H31: =H7+H12+H17+H22 -> 1382 | I31: =I7+I12+I17+I22 -> 1624 | J31: =J7+J12+J17+J22 -> 1727 | K31: =K7+K12+K17+K22 -> 1999 | L31: =SUM(AF31:AH31)+AJ31 -> 2075 | M31: =L31/K31-1 -> 0.03801901 | N31: =N7+N12+N17+N22 -> 2330 | O31: =O7+O12+O17+O22 -> 2560 | Q31: =Q7+Q12+Q17+Q22 -> 371 | R31: =R7+R12+R17+R22 -> 347 | S31: =S7+S12+S17+S22 -> 296 | T31: =T7+T12+T17+T22 -> 368 | V31: =V7+V12+V17+V22 -> 465 | W31: =W7+W12+W17+W22 -> 382 | X31: =X7+X12+X17+X22 -> 390 | Y31: =Y7+Y12+Y17+Y22 -> 387 | AA31: =AA7+AA12+AA17+AA22 -> 486 | AB31: =AB7+AB12+AB17+AB22 -> 408 | AC31: =AC7+AC12+AC17+AC22 -> 403 | AD31: =AD7+AD12+AD17+AD22 -> 430 | AF31: =AF7+AF12+AF17+AF22 -> 531 | AG31: =AG7+AG12+AG17+AG22 -> 479 | AH31: =AH7+AH12+AH17+AH22 -> 487 | AI31: =AI7+AI12+AI17+AI22 -> 502 | AJ31: =AJ7+AJ12+AJ17+AJ22 -> 578 | AK31: =AJ31/AI31-1 -> 0.15139442 | AM31: =AM7+AM12+AM17+AM22 -> 595 | AN31: =AN7+AN12+AN17+AN22 -> 563 | AO31: =AO7+AO12+AO17+AO22 -> 589 | AP31: =AP7+AP12+AP17+AP22 -> 583
A32: Revenues | B32: 30601 | C32: 32376 | D32: 34350 | E32: 36397 | F32: 39117 | G32: 37403 | H32: =H27+H26+H25 -> 44538 | I32: =I27+I26+I25 -> 46710 | J32: =J27+J26+J25 -> 51217 | K32: =K27+K26+K25 -> 51829 | L32: =SUM(AF32:AH32)+AJ32 -> 51362 | M32: =L32/K32-1 -> -0.0090103996 | N32: =SUM(AM32:AP32) -> 54429 | O32: =O27+O26+O25 -> 57770 | Q32: 10594 | R32: 11243 | S32: 10357 | T32: 12344 | V32: 12248 | W32: 11357 | X32: 10871 | Y32: =Y27+Y26+Y25 -> 12234 | AA32: =AA27+AA26+AA25 -> 12687 | AB32: =AB27+AB26+AB25 -> 13315 | AC32: =AC27+AC26+AC25 -> 12390 | AD32: =AD27+AD26+AD25 -> 12825 | AF32: =AF27+AF26+AF25 -> 12939 | AG32: =AG27+AG26+AG25 -> 13388 | AH32: =AH27+AH26+AH25 -> 12429 | AI32: =AI27+AI26+AI25 -> 13073 | AJ32: 12606 | AK32: =AJ32/AI32-1 -> -0.035722481 | AM32: =AM27+AM26+AM25 -> 13620 | AN32: =AN27+AN26+AN25 -> 14155 | AO32: =AO27+AO26+AO25 -> 12988 | AP32: =AP27+AP26+AP25 -> 13666
A33: Cost of sales | B33: 16534 | C33: 17405 | D33: 19038 | E33: 20441 | F33: 21643 | G33: 21162 | H33: 24576 | I33: 25231 | J33: 28925 | K33: =AF33+AG33+AH33+AI33 -> 28803 | L33: =SUM(AF33:AH33)+AJ33 -> 28475 | M33: =L33/K33-1 -> -0.011387703 | N33: =SUM(AM33:AP33) -> 29450 | O33: 31500 | Q33: 5853 | R33: 6396 | S33: 5638 | T33: 6689 | V33: 6552 | W33: 6144 | X33: 5804 | Y33: 6731 | AA33: 7072 | AB33: 7604 | AC33: 7019 | AD33: 7230 | AF33: 7219 | AG33: 7417 | AH33: 6867 | AI33: 7300 | AJ33: 6972 | AK33: =AJ33/AI33-1 -> -0.044931507 | AM33: 7350 | AN33: 7500 | AO33: 7100 | AP33: 7500
A34: Gross profit | B34: 14067 | C34: 14971 | D34: 15312 | E34: 15956 | F34: 17474 | G34: =G32-G33 -> 16241 | H34: =H32-H33 -> 19962 | I34: =I32-I33 -> 21479 | J34: =J32-J33 -> 22292 | K34: =K32-K33 -> 23026 | L34: =L32-L33 -> 22887 | M34: =L34/K34-1 -> -0.0060366542 | N34: =SUM(AM34:AP34) -> 24979 | O34: =O32-O33 -> 26270 | Q34: 4741 | R34: 4847 | S34: 4719 | T34: 5655 | V34: 5696 | W34: 5213 | X34: 5067 | Y34: =Y32-Y33 -> 5503 | AA34: =AA32-AA33 -> 5615 | AB34: =AB32-AB33 -> 5711 | AC34: =AC32-AC33 -> 5371 | AD34: =AD32-AD33 -> 5595 | AF34: =AF32-AF33 -> 5720 | AG34: =AG32-AG33 -> 5971 | AH34: =AH32-AH33 -> 5562 | AI34: =AI32-AI33 -> 5773 | AJ34: =AJ32-AJ33 -> 5634 | AK34: =AJ34/AI34-1 -> -0.024077603 | AM34: =AM32-AM33 -> 6270 | AN34: =AN32-AN33 -> 6655 | AO34: =AO32-AO33 -> 5888 | AP34: =AP32-AP33 -> 6166
A35: Demand creation expense | B35: 3213 | C35: 3278 | D35: 3341 | E35: 3577 | F35: 3753 | G35: 3592 | H35: 3114 | I35: 3850 | J35: =AA35+AB35+AC35+AD35 -> 4060 | K35: =AF35+AG35+AH35+AI35 -> 4344 | L35: =SUM(AF35:AH35)+AJ35 -> 4285 | M35: =L35/K35-1 -> -0.013581952 | N35: =SUM(AM35:AP35) -> 4720 | O35: 5100 | Q35: 677 | R35: 729 | S35: 711 | T35: 997 | V35: 918 | W35: 1017 | X35: 854 | Y35: 1061 | AA35: 943 | AB35: 1102 | AC35: 923 | AD35: 1092 | AF35: 1069 | AG35: 1114 | AH35: 1011 | AI35: 1150 | AJ35: 1091 | AK35: =AJ35/AI35-1 -> -0.051304348 | AM35: 1200 | AN35: 1200 | AO35: 1100 | AP35: 1220
A36: Operating overhead expense | B36: 6679 | C36: 7191 | D36: 7222 | E36: 7934 | F36: 8949 | G36: 9534 | H36: 9911 | I36: 10954 | J36: =AA36+AB36+AC36+AD36 -> 12317 | K36: =AF36+AG36+AH36+AI36 -> 12724 | L36: =SUM(AF36:AH36)+AJ36 -> 12291 | M36: =L36/K36-1 -> -0.034030179 | N36: =SUM(AM36:AP36) -> 13200 | O36: 13700 | Q36: 2298 | R36: 2538 | S36: 2330 | T36: 2745 | V36: 2654 | W36: 2742 | X36: 2584 | Y36: 2974 | AA36: 2977 | AB36: 3022 | AC36: 3036 | AD36: 3282 | AF36: 3047 | AG36: 3032 | AH36: 3215 | AI36: 3430 | AJ36: 2997 | AK36: =AJ36/AI36-1 -> -0.12623907 | AM36: 3100 | AN36: 3100 | AO36: 3400 | AP36: 3600
A37: Total selling and administrative expense | B37: 9892 | C37: 10469 | D37: 10563 | E37: 11511 | F37: 12702 | G37: 13126 | H37: 13025 | I37: 14804 | J37: =AA37+AB37+AC37+AD37 -> 16377 | K37: =AF37+AG37+AH37+AI37 -> 16788 | L37: =SUM(AF37:AH37)+AJ37 -> 16576 | M37: =L37/K37-1 -> -0.012628068 | N37: =SUM(AM37:AP37) -> 17250 | O37: 17700 | Q37: 2975 | R37: 3267 | S37: 3041 | T37: 3742 | V37: 3572 | W37: 3759 | X37: 3438 | Y37: 4035 | AA37: 3920 | AB37: 4124 | AC37: 3959 | AD37: 4374 | AF37: 4116 | AG37: 4146 | AH37: 4226 | AI37: 4300 | AJ37: 4088 | AK37: =AJ37/AI37-1 -> -0.049302326 | AM37: 4300 | AN37: 4200 | AO37: 4350 | AP37: 4400
A38: Total Operating Expenses | B38: =B35+B36+B37 -> 19784 | C38: =C35+C36+C37 -> 20938 | D38: =D35+D36+D37 -> 21126 | E38: =E35+E36+E37 -> 23022 | F38: =F35+F36+F37 -> 25404 | G38: =G35+G36+G37 -> 26252 | H38: =H35+H36+H37 -> 26050 | I38: =I35+I36+I37 -> 29608 | ... L38: =L35+L36+L37 -> 33152 | M38: =L38/K38-1 -> -0.020793951 | N38: =N35+N36+N37 -> 35170 | O38: =O35+O36+O37 -> 36500 | Q38: =Q35+Q36+Q37 -> 5950 | R38: =R35+R36+R37 -> 6534 | S38: =S35+S36+S37 -> 6082 | T38: =T35+T36+T37 -> 7484 | V38: =V35+V36+V37 -> 7144 | W38: =W35+W36+W37 -> 7518 | X38: =X35+X36+X37 -> 6876 | Y38: =Y35+Y36+Y37 -> 8070 | AA38: =AA35+AA36+AA37 -> 7840 | AB38: =AB35+AB36+AB37 -> 8248 | AC38: =AC35+AC36+AC37 -> 7918 | AD38: =AD35+AD36+AD37 -> 8748 | AF38: =AF35+AF36+AF37 -> 8232 | AG38: =AG35+AG36+AG37 -> 8292 | AH38: =AH35+AH36+AH37 -> 8452 | AI38: =AI35+AI36+AI37 -> 8880 | AJ38: =AJ35+AJ36+AJ37 -> 8176 | AK38: =AJ38/AI38-1 -> -0.079279279 | AM38: =AM35+AM36+AM37 -> 8600 | AN38: =AN35+AN36+AN37 -> 8500 | AO38: =AO35+AO36+AO37 -> 8850 | AP38: =AP35+AP36+AP37 -> 9220
A39: Operating Income | B39: =B34-B37 -> 4175 | C39: =C34-C37 -> 4502 | D39: =D34-D37 -> 4749 | E39: =E34-E37 -> 4445 | F39: =F34-F37 -> 4772 | G39: =G34-G37 -> 3115 | H39: =H34-H37 -> 6937 | I39: =I34-I37 -> 6675 | ... L39: =L34-L37 -> 6311 | M39: =L39/K39-1 -> 0.011702469 | N39: =N34-N37 -> 7729 | O39: =O34-O37 -> 8570 | Q39: 1766 | R39: 1580 | S39: 1678 | T39: 1913 | V39: 2124 | W39: 1454 | X39: 1629 | Y39: =Y34-Y37 -> 1468 | AA39: =AA34-AA37 -> 1695 | AB39: =AB34-AB37 -> 1587 | AC39: =AC34-AC37 -> 1412 | AD39: =AD34-AD37 -> 1221 | AF39: =AF34-AF37 -> 1604 | AG39: =AG34-AG37 -> 1825 | AH39: =AH34-AH37 -> 1336 | AI39: =AI34-AI37 -> 1473 | AJ39: =AJ34-AJ37 -> 1546 | AK39: =AJ39/AI39-1 -> 0.049558724 | AM39: =AM34-AM37 -> 1970 | AN39: =AN34-AN37 -> 2455 | AO39: =AO34-AO37 -> 1538 | AP39: =AP34-AP37 -> 1766
A40: Interest expense (income), net | B40: 28 | C40: 19 | D40: 59 | E40: 54 | F40: 49 | G40: 89 | H40: 262 | I40: 205 | J40: =AA40+AB40+AC40+AD40 -> -6 | K40: =AF40+AG40+AH40+AI40 -> -158 | L40: =SUM(AF40:AH40)+AJ40 -> -161 | M40: =L40/K40-1 -> 0.018987342 | N40: =SUM(AM40:AP40) -> -143 | O40: -120 | Q40: 65 | R40: 70 | S40: 64 | T40: 63 | V40: 57 | W40: 55 | X40: 53 | Y40: 40 | AA40: 13 | AB40: 16 | AC40: -7 | AD40: -28 | AF40: -34 | AG40: -22 | AH40: -52 | AI40: -50 | AJ40: -53 | AK40: =AJ40/AI40-1 -> 0.06 | AM40: -30 | AN40: -20 | AO40: -48 | AP40: -45
...

Sheet Balance Sheet
A1: Consolidated Balance Sheets - USD ($) $ in Millions | B1: May 31, 2015 | C1: May 31, 2016 | D1: May 31, 2017 | E1: May 31, 2018 | F1: May 31, 2019 | G1: May 31, 2020 | H1: May 31, 2021 | I1: May 31, 2022 | J1: May 31, 2023 | K1: May 31, 2024
A2: Current assets:
A3: Cash and equivalents | B3: $ 3,852 | C3: 3138 | D3: 3808 | E3: $ 4,249 | F3: 4466 | G3: 8348 | H3: 9889 | I3: 8574 | J3: 7441 | K3: 9860
A4: Short-term investments | B4: 2072 | C4: 2319 | D4: 2371 | E4: 996 | F4: 197 | G4: 439 | H4: 3587 | I4: 4423 | J4: 3234 | K4: 1722
A5: Accounts receivable, net | B5: 3358 | C5: 3241 | D5: 3677 | E5: 3498 | F5: 4272 | G5: 2749 | H5: 4463 | I5: 4667 | J5: 4131 | K5: 4427
A6: Inventories | B6: 4337 | C6: 4838 | D6: 5055 | E6: 5261 | F6: 5622 | G6: 7367 | H6: 6854 | I6: 8420 | J6: 8454 | K6: 7519
A7: Prepaid expenses and other current assets | B7: 1968 | C7: 1489 | D7: 1150 | E7: 1130 | F7: 1968 | G7: 1653 | H7: 1498 | I7: 2129 | J7: 1942 | K7: 1854
A8: Total current assets | B8: 15587 | C8: 15025 | D8: 16061 | E8: 15134 | F8: 16525 | G8: 20556 | H8: 26291 | I8: 28213 | J8: 25202 | K8: 25382
A9: Property, plant and equipment, net | B9: 3011 | C9: 3520 | D9: 3989 | E9: 4454 | F9: 4744 | G9: 4866 | H9: 4904 | I9: 4791 | J9: 5081 | K9: 5000
A10: Operating lease right-of-use assets, net | B10: 0 | C10: 0 | D10: 0 | E10: 0 | F10: 0 | G10: 3097 | H10: 3113 | I10: 2926 | J10: 2923 | K10: 2718
A11: Identifiable intangible assets, net | B11: 281 | C11: 281 | D11: 283 | E11: 285 | F11: 283 | G11: 274 | H11: 269 | I11: 286 | J11: 274 | K11: 259
A12: Goodwill | B12: 131 | C12: 131 | D12: 139 | E12: 154 | F12: 154 | G12: 223 | H12: 242 | I12: 284 | J12: 281 | K12: 240
A13: Deferred income taxes and other assets | B13: 2587 | C13: 2422 | D13: 2787 | E13: 2509 | F13: 2011 | G13: 2326 | H13: 2921 | I13: 3821 | J13: 3770 | K13: 4511
A14: TOTAL ASSETS | B14: 21597 | C14: 21379 | D14: 23259 | E14: 22536 | F14: 23717 | G14: 31342 | H14: 37740 | I14: 40321 | J14: 37531 | K14: 38110
A15: Current liabilities:
A16: Current portion of long-term debt | B16: 107 | C16: 44 | D16: 6 | E16: 6 | F16: 6 | G16: 3 | H16: 0 | I16: 500 | J16: 0 | K16: 1000
A17: Notes payable | B17: 74 | C17: 1 | D17: 325 | E17: 336 | F17: 9 | G17: 248 | H17: 2 | I17: 10 | J17: 6 | K17: 6
A18: Accounts payable | B18: 2131 | C18: 2191 | D18: 2048 | E18: 2279 | F18: 2612 | G18: 2248 | H18: 2836 | I18: 3358 | J18: 2862 | K18: 2851
A19: Current portion of operating lease liabilities | B19: 0 | C19: 0 | D19: 0 | E19: 0 | F19: 0 | G19: 445 | H19: 467 | I19: 420 | J19: 425 | K19: 477
A20: Accrued liabilities | B20: 3949 | C20: 3037 | D20: 3011 | E20: 3269 | F20: 5010 | G20: 5184 | H20: 6063 | I20: 6220 | J20: 5723 | K20: 5725
A21: Income taxes payable | B21: 71 | C21: 85 | D21: 84 | E21: 150 | F21: 229 | G21: 156 | H21: 306 | I21: 222 | J21: 240 | K21: 534
A22: Total current liabilities | B22: 6332 | C22: 5358 | D22: 5474 | E22: 6040 | F22: 7866 | G22: 8284 | H22: 9674 | I22: 10730 | J22: 9256 | K22: 10593
A23: Long-term debt | B23: 1079 | C23: 1993 | D23: 3471 | E23: 3468 | F23: 3464 | G23: 9406 | H23: 9413 | I23: 8920 | J23: 8927 | K23: 7903
A24: Operating lease liabilities | B24: 0 | C24: 0 | D24: 0 | E24: 0 | F24: 0 | G24: 2913 | H24: 2931 | I24: 2777 | J24: 2786 | K24: 2566
A25: Deferred income taxes and other liabilities | B25: 1479 | C25: 1770 | D25: 1907 | E25: 3216 | F25: 3347 | G25: 2684 | H25: 2955 | I25: 2613 | J25: 2558 | K25: 2618
A26: Commitments and contingencies (Note 16)
A27: Redeemable preferred stock | B27: 0 | C27: 0 | D27: 0 | E27: 0 | F27: 0 | G27: 0 | H27: 0 | I27: 0 | J27: 0 | K27: 0
A28: Shareholders' equity:
A29: Capital in excess of stated value | B29: 6773 | C29: 7786 | D29: 8638 | E29: 6384 | F29: 7163 | G29: 8299 | H29: 9965 | I29: 11484 | J29: 12412 | K29: 13409
A30: Accumulated other comprehensive income (loss) | B30: 1246 | C30: 318 | D30: -213 | E30: -92 | F30: 231 | G30: -56 | H30: -380 | I30: 318 | J30: 231 | K30: 53
A31: Retained earnings (deficit) | B31: 4685 | C31: 4151 | D31: 3979 | E31: 3517 | F31: 1643 | G31: -191 | H31: 3179 | I31: 3476 | J31: 1358 | K31: 965
A32: Total shareholders' equity | B32: 12707 | C32: 12258 | D32: 12407 | E32: 9812 | F32: 9040 | G32: 8055 | H32: 12767 | I32: 15281 | J32: 14004 | K32: 14430
A33: TOTAL LIABILITIES AND SHAREHOLDERS' EQUITY | B33: 21597 | C33: 21379 | D33: 23259 | E33: 22536 | F33: 23717 | G33: 31342 | H33: 37740 | I33: 40321 | J33: 37531 | K33: 38110
A34: Class A Convertible Common Stock
A35: Shareholders' equity:
A36: Common stock at stated value | B36: 0 | C36: 0 | D36: 0 | E36: 0 | F36: 0 | G36: 0 | H36: 0 | I36: 0 | J36: 0 | K36: 0
A37: Class B Common Stock
A38: Shareholders' equity:
A39: Common stock at stated value | B39: $ 3 | C39: 3 | D39: 3 | E39: $ 3 | F39: 3 | G39: 3 | H39: 3 | I39: 3 | J39: 3 | K39: 3

Sheet Statement of Operations
A1: Consolidated Statements of Income - USD ($) shares in Millions, $ in Millions | B1: 12 Months Ended | M1: 2021 | R1: 2022 | W1: 2023 | AB1: 2024
B2: May 31, 2015 | C2: May 31, 2016 | D2: May 31, 2017 | E2: May 31, 2018 | F2: May 31, 2019 | G2: May 31, 2020 | H2: May 31, 2021 | I2: May 31, 2022 | J2: May 31, 2023 | K2: May 31, 2024 | M2: Aug. 31, 2020 | N2: Nov. 30, 2020 | O2: Feb. 28, 2021 | P2: May. 31, 2021 | R2: Aug. 31, 2021 | S2: Nov. 30, 2021 | T2: Feb. 28, 2022 | U2: May. 31, 2022 | W2: Aug. 31, 2022 | X2: Nov. 30, 2022 | Y2: Feb. 28, 2023 | Z2: May. 31, 2023 | AB2: Aug. 31, 2023 | AC2: Nov. 30, 2023 | AD2: Feb. 29, 2024 | AE2: May. 31, 2024
A3: Income Statement [Abstract]
A4: Revenues | B4: 30601 | C4: 32376 | D4: 34350 | E4: 36397 | F4: 39117 | G4: 37403 | H4: 44538 | I4: 46710 | J4: 51217 | K4: 51362 | M4: 10594 | N4: 11243 | O4: 10357 | P4: 12344 | R4: 12248 | S4: 11357 | T4: 10871 | U4: 12234 | W4: 12687 | X4: 13315 | Y4: 12390 | Z4: 12825 | AB4: 12939 | AC4: 13388 | AD4: 12429 | AE4: =K4-SUM(AB4:AD4) -> 12606
A5: Cost of sales | B5: 16534 | C5: 17405 | D5: 19038 | E5: 20441 | F5: 21643 | G5: 21162 | H5: 24576 | I5: 25231 | J5: 28925 | K5: 28475 | M5: 5853 | N5: 6396 | O5: 5638 | P5: 6689 | R5: 6552 | S5: 6144 | T5: 5804 | U5: 6731 | W5: 7072 | X5: 7604 | Y5: 7019 | Z5: 7230 | AB5: 7219 | AC5: 7417 | AD5: 6867 | AE5: =K5-SUM(AB5:AD5) -> 6972
A6: Gross profit | B6: =B4-B5 -> 14067 | C6: =C4-C5 -> 14971 | D6: =D4-D5 -> 15312 | E6: =E4-E5 -> 15956 | F6: =F4-F5 -> 17474 | G6: =G4-G5 -> 16241 | H6: =H4-H5 -> 19962 | I6: =I4-I5 -> 21479 | ... K6: =K4-K5 -> 22887 | M6: =M4-M5 -> 4741 | N6: =N4-N5 -> 4847 | O6: =O4-O5 -> 4719 | P6: =P4-P5 -> 5655 | R6: =R4-R5 -> 5696 | S6: =S4-S5 -> 5213 | T6: =T4-T5 -> 5067 | U6: =U4-U5 -> 5503 | W6: =W4-W5 -> 5615 | X6: =X4-X5 -> 5711 | Y6: =Y4-Y5 -> 5371 | Z6: =Z4-Z5 -> 5595 | AB6: =AB4-AB5 -> 5720 | AC6: =AC4-AC5 -> 5971 | AD6: =AD4-AD5 -> 5562 | AE6: =AE4-AE5 -> 5634
A7: Demand creation expense | B7: 3213 | C7: 3278 | D7: 3341 | E7: 3577 | F7: 3753 | G7: 3592 | H7: 3114 | I7: 3850 | J7: 4060 | K7: 4285 | M7: 677 | N7: 729 | O7: 711 | P7: 997 | R7: 918 | S7: 1017 | T7: 854 | U7: 1061 | W7: 943 | X7: 1102 | Y7: 923 | Z7: 1092 | AB7: 1069 | AC7: 1114 | AD7: 1011 | AE7: =K7-SUM(AB7:AD7) -> 1091
A8: Operating overhead expense | B8: 6679 | C8: 7191 | D8: 7222 | E8: 7934 | F8: 8949 | G8: 9534 | H8: 9911 | I8: 10954 | J8: 12317 | K8: 12291 | M8: 2298 | N8: 2538 | O8: 2330 | P8: 2745 | R8: 2654 | S8: 2742 | T8: 2584 | U8: 2974 | W8: 2977 | X8: 3022 | Y8: 3036 | Z8: 3282 | AB8: 3047 | AC8: 3032 | AD8: 3215 | AE8: =K8-SUM(AB8:AD8) -> 2997
A9: Total selling and administrative expense | B9: 9892 | C9: 10469 | D9: 10563 | E9: 11511 | F9: 12702 | G9: 13126 | H9: 13025 | I9: 14804 | J9: 16377 | K9: 16576 | M9: 2975 | N9: 3267 | O9: 3041 | P9: 3742 | R9: 3572 | S9: 3759 | T9: 3438 | U9: 4035 | W9: 3920 | X9: 4124 | Y9: 3959 | Z9: 4374 | AB9: 4116 | AC9: 4146 | AD9: 4226 | AE9: =K9-SUM(AB9:AD9) -> 4088
A10: Operating Income | B10: =B6-B9 -> 4175 | C10: =C6-C9 -> 4502 | D10: =D6-D9 -> 4749 | E10: =E6-E9 -> 4445 | F10: =F6-F9 -> 4772 | G10: =G6-G9 -> 3115 | H10: =H6-H9 -> 6937 | I10: =I6-I9 -> 6675 | ... K10: =K6-K9 -> 6311 | M10: =M6-M9 -> 1766 | N10: =N6-N9 -> 1580 | O10: =O6-O9 -> 1678 | P10: =P6-P9 -> 1913 | R10: =R6-R9 -> 2124 | S10: =S6-S9 -> 1454 | T10: =T6-T9 -> 1629 | U10: =U6-U9 -> 1468 | W10: =W6-W9 -> 1695 | X10: =X6-X9 -> 1587 | Y10: =Y6-Y9 -> 1412 | Z10: =Z6-Z9 -> 1221 | AB10: =AB6-AB9 -> 1604 | AC10: =AC6-AC9 -> 1825 | AD10: =AD6-AD9 -> 1336 | AE10: =AE6-AE9 -> 1546
A11: Interest expense (income), net | B11: 28 | C11: 19 | D11: 59 | E11: 54 | F11: 49 | G11: 89 | H11: 262 | I11: 205 | J11: -6 | K11: -161 | M11: 65 | N11: 70 | O11: 64 | P11: 63 | R11: 57 | S11: 55 | T11: 53 | U11: 40 | W11: 13 | X11: 16 | Y11: -7 | Z11: -28 | AB11: -34 | AC11: -22 | AD11: -52 | AE11: =K11-SUM(AB11:AD11) -> -53
A12: Other (income) expense, net | B12: -58 | C12: -140 | D12: -196 | E12: 66 | F12: -78 | G12: 139 | H12: 14 | I12: -181 | J12: -280 | K12: -228 | M12: -14 | N12: 54 | O12: -22 | P12: -4 | R12: -39 | S12: -102 | T12: -94 | U12: 54 | W12: -146 | X12: -79 | Y12: -58 | Z12: 3 | AB12: -10 | AC12: -75 | AD12: -16 | AE12: =K12-SUM(AB12:AD12) -> -127
A13: Income before income taxes | B13: 4205 | C13: 4623 | D13: 4886 | E13: 4325 | F13: 4801 | G13: 2887 | H13: 6661 | I13: 6651 | J13: 6201 | K13: 6700 | M13: 1715 | N13: 1456 | O13: 1636 | P13: =P10-P11-P12 -> 1854 | R13: =R10-R11-R12 -> 2106 | S13: =S10-S11-S12 -> 1501 | T13: =T10-T11-T12 -> 1670 | U13: =U10-U11-U12 -> 1374 | W13: 1828 | X13: 1650 | Y13: 1477 | Z13: 1246 | AB13: 1648 | AC13: 1922 | AD13: 1404 | AE13: =K13-SUM(AB13:AD13) -> 1726
A14: Income tax expense | B14: 932 | C14: 863 | D14: 646 | E14: 2392 | F14: 772 | G14: 348 | H14: 934 | I14: 605 | J14: 1131 | K14: 1000 | M14: 197 | N14: 205 | O14: 187 | P14: 345 | R14: 232 | S14: 164 | T14: 274 | U14: -65 | W14: 360 | X14: 319 | Y14: 237 | Z14: 215 | AB14: 198 | AC14: 344 | AD14: 232 | AE14: =K14-SUM(AB14:AD14) -> 226
A15: NET INCOME | B15: 3273 | C15: 3760 | D15: 4240 | E15: 1933 | F15: 4029 | G15: 2539 | H15: 5727 | I15: 6046 | J15: 5070 | K15: 5700 | M15: 1518 | N15: 1251 | O15: 1449 | P15: =P13-P14 -> 1509 | R15: =R13-R14 -> 1874 | S15: =S13-S14 -> 1337 | T15: =T13-T14 -> 1396 | U15: =U13-U14 -> 1439 | W15: 1468 | X15: 1331 | Y15: 1240 | Z15: 1031 | AB15: 1450 | AC15: 1578 | AD15: 1172 | AE15: =K15-SUM(AB15:AD15) -> 1500
A16: Earnings per common share:
A17: Basic (in dollars per share) | B17: 1.9 | C17: 2.21 | D17: 2.56 | E17: 1.19 | F17: 2.55 | G17: 1.63 | H17: =H15/H20 -> 3.6408137 | I17: =I15/I20 -> 3.8294908 | J17: =J15/J20 -> 3.2675947 | K17: 3.76 | M17: 0.97 | N17: 0.8 | O17: 0.92 | P17: =P$15/P20 -> 0.95566814 | R17: 1.18 | S17: 0.84 | T17: 0.88 | U17: =U15/U20 -> 0.9153944 | W17: 0.94 | X17: 0.85 | Y17: 0.8 | Z17: =Z15/Z20 -> 0.67100553 | AB17: 0.95 | AC17: 1.04 | AD17: 0.77
A18: Diluted (in dollars per share) | B18: 1.85 | C18: 2.16 | D18: 2.51 | E18: 1.17 | F18: 2.49 | G18: 1.6 | H18: =H15/H21 -> 3.558469 | I18: =I15/I21 -> 3.7534145 | J18: =J15/J21 -> 3.2297108 | K18: 3.73 | M18: 0.95 | N18: 0.78 | O18: 0.9 | P18: =P$15/P21 -> 0.93442318 | R18: 1.16 | S18: 0.83 | T18: 0.87 | U18: =U15/U21 -> 0.90219436 | W18: 0.93 | X18: 0.85 | Y18: 0.79 | Z18: =Z15/Z21 -> 0.66246868 | AB18: 0.94 | AC18: 1.03 | AD18: 0.77
A19: Weighted average common shares outstanding:
A20: Basic (in shares) | B20: =B15/B17 -> 1722.6316 | C20: =C15/C17 -> 1701.3575 | D20: =D15/D17 -> 1656.25 | E20: 1623.8 | F20: 1579.7 | G20: 1558.8 | H20: 1573 | I20: 1578.8 | J20: 1551.6 | K20: 1517.6 | M20: 1561.8 | N20: 1573 | O20: 1578 | P20: 1579 | R20: 1581.9 | S20: 1582.4 | T20: 1579 | U20: 1572 | W20: 1567.1 | X20: 1559 | Y20: 1543.8 | Z20: 1536.5 | AB20: 1528.4 | AC20: 1520.8 | AD20: 1513.2
A21: Diluted (in shares) | B21: =B15/B18 -> 1769.1892 | C21: =C15/C18 -> 1740.7407 | D21: =D15/D18 -> 1689.243 | E21: 1659.1 | F21: 1618.4 | G21: 1591.6 | H21: 1609.4 | I21: 1610.8 | J21: 1569.8 | K21: 1529.7 | M21: 1593.3 | N21: 1609.5 | O21: 1616.9 | P21: 1614.9 | R21: 1619.6 | S21: 1617.4 | T21: 1610.7 | U21: 1595 | W21: 1585.8 | X21: 1572.4 | Y21: 1564.8 | Z21: 1556.3 | AB21: 1543.3 | AC21: 1532.1 | AD21: 1526.5
A23: Ratios
A24: Gross Margin | B24: =B6/B4 -> 0.45969086 | C24: =C6/C4 -> 0.46241043 | D24: =D6/D4 -> 0.44576419 | E24: =E6/E4 -> 0.43838778 | F24: =F6/F4 -> 0.44671115 | G24: =G6/G4 -> 0.43421651 | H24: =H6/H4 -> 0.44820154 | I24: =I6/I4 -> 0.45983729 | ... K24: =K6/K4 -> 0.44560181 | R24: =R6/R4 -> 0.46505552 | S24: =S6/S4 -> 0.45901206 | T24: =T6/T4 -> 0.46610247 | U24: =U6/U4 -> 0.449812 | W24: =W6/W4 -> 0.44257902 | X24: =X6/X4 -> 0.42891476 | Y24: =Y6/Y4 -> 0.43349475 | Z24: =Z6/Z4 -> 0.43625731 | AB24: =AB6/AB4 -> 0.44207435 | AC24: =AC6/AC4 -> 0.44599641 | AD24: =AD6/AD4 -> 0.44750181 | AE24: =AE6/AE4 -> 0.44693003
A25: Total Operating Expense/Revenues | B25: =B9/B4 -> 0.32325741 | C25: =C9/C4 -> 0.32335681 | D25: =D9/D4 -> 0.30751092 | E25: =E9/E4 -> 0.31626233 | F25: =F9/F4 -> 0.32471815 | G25: =G9/G4 -> 0.35093442 | H25: =H9/H4 -> 0.2924469 | I25: =I9/I4 -> 0.31693428 | ... K25: =K9/K4 -> 0.32272887 | R25: =R9/R4 -> 0.29163945 | S25: =S9/S4 -> 0.3309853 | T25: =T9/T4 -> 0.31625425 | U25: =U9/U4 -> 0.32981854 | W25: =W9/W4 -> 0.30897769 | X25: =X9/X4 -> 0.30972587 | Y25: =Y9/Y4 -> 0.31953188 | Z25: =Z9/Z4 -> 0.34105263 | AB25: =AB9/AB4 -> 0.31810805 | AC25: =AC9/AC4 -> 0.30968031 | AD25: =AD9/AD4 -> 0.34001126 | AE25: =AE9/AE4 -> 0.32429002
A26: Operating Margin | B26: =B10/B4 -> 0.13643345 | C26: =C10/C4 -> 0.13905362 | D26: =D10/D4 -> 0.13825328 | E26: =E10/E4 -> 0.12212545 | F26: =F10/F4 -> 0.121993 | G26: =G10/G4 -> 0.08328209 | H26: =H10/H4 -> 0.15575464 | I26: =I10/I4 -> 0.14290302 | ... K26: =K10/K4 -> 0.12287294 | R26: =R10/R4 -> 0.17341607 | S26: =S10/S4 -> 0.12802677 | T26: =T10/T4 -> 0.14984822 | U26: =U10/U4 -> 0.11999346 | W26: =W10/W4 -> 0.13360132 | X26: =X10/X4 -> 0.11918888 | Y26: =Y10/Y4 -> 0.11396287 | Z26: =Z10/Z4 -> 0.095204678 | AB26: =AB10/AB4 -> 0.1239663 | AC26: =AC10/AC4 -> 0.1363161 | AD26: =AD10/AD4 -> 0.10749055 | AE26: =AE10/AE4 -> 0.12264001
A27: Net Margin | B27: =B15/B4 -> 0.10695729 | C27: =C15/C4 -> 0.11613541 | D27: =D15/D4 -> 0.12343523 | E27: =E15/E4 -> 0.053108773 | F27: =F15/F4 -> 0.1029987 | G27: =G15/G4 -> 0.067882255 | H27: =H15/H4 -> 0.12858682 | I27: =I15/I4 -> 0.12943695 | ... K27: =K15/K4 -> 0.11097699 | R27: =R15/R4 -> 0.15300457 | S27: =S15/S4 -> 0.11772475 | T27: =T15/T4 -> 0.12841505 | U27: =U15/U4 -> 0.11762302 | W27: =W15/W4 -> 0.11570899 | X27: =X15/X4 -> 0.099962448 | Y27: =Y15/Y4 -> 0.10008071 | Z27: =Z15/Z4 -> 0.080389864 | AB27: =AB15/AB4 -> 0.1120643 | AC27: =AC15/AC4 -> 0.11786675 | AD27: =AD15/AD4 -> 0.094295599 | AE27: =AE15/AE4 -> 0.11899096
A28: Effective Tax Rate | B28: =B14/B13 -> 0.2216409 | C28: =C14/C13 -> 0.18667532 | D28: =D14/D13 -> 0.13221449 | E28: =E14/E13 -> 0.55306358 | F28: =F14/F13 -> 0.16079983 | G28: =G14/G13 -> 0.12054035 | H28: =H14/H13 -> 0.14021919 | I28: =I14/I13 -> 0.090963765 | ... K28: =K14/K13 -> 0.14925373 | M28: =M14/M13 -> 0.1148688 | N28: =N14/N13 -> 0.1407967 | O28: =O14/O13 -> 0.11430318 | P28: =P14/P13 -> 0.18608414 | R28: =R14/R13 -> 0.11016144 | S28: =S14/S13 -> 0.10926049 | T28: =T14/T13 -> 0.16407186 | U28: =U14/U13 -> -0.047307132 | W28: =W14/W13 -> 0.19693654 | X28: =X14/X13 -> 0.19333333 | Y28: =Y14/Y13 -> 0.16046039 | Z28: =Z14/Z13 -> 0.17255217 | AB28: =AB14/AB13 -> 0.12014563 | AC28: =AC14/AC13 -> 0.17898023 | AD28: =AD14/AD13 -> 0.16524217 | AE28: =AE14/AE13 -> 0.13093859
A30: Growth Rates
A31: Revenues | C31: =(C4-B4)/ABS(B4) -> 0.05800464 | D31: =(D4-C4)/ABS(C4) -> 0.06097109 | E31: =(E4-D4)/ABS(D4) -> 0.059592431 | F31: =(F4-E4)/ABS(E4) -> 0.074731434 | G31: =(G4-F4)/ABS(F4) -> -0.043817266 | H31: =(H4-G4)/ABS(G4) -> 0.1907601 | I31: =(I4-H4)/ABS(H4) -> 0.048767345 | J31: =(J4-I4)/ABS(I4) -> 0.096488975 | K31: =(K4-J4)/ABS(J4) -> 0.0028310912 | R31: =(R4-M4)/ABS(M4) -> 0.15612611 | S31: =(S4-N4)/ABS(N4) -> 0.010139642 | T31: =(T4-O4)/ABS(O4) -> 0.049628271 | U31: =(U4-P4)/ABS(P4) -> -0.0089112119 | W31: =(W4-R4)/ABS(R4) -> 0.035842587 | X31: =(X4-S4)/ABS(S4) -> 0.17240468 | Y31: =(Y4-T4)/ABS(T4) -> 0.13972956 | Z31: =(Z4-U4)/ABS(U4) -> 0.048307994 | AB31: =(AB4-W4)/ABS(W4) -> 0.019862852 | AC31: =(AC4-X4)/ABS(X4) -> 0.0054825385 | AD31: =(AD4-Y4)/ABS(Y4) -> 0.0031476998 | AE31: =(AE4-Z4)/ABS(Z4) -> -0.017076023
A32: Cost of sales | C32: =(C5-B5)/ABS(B5) -> 0.052679327 | D32: =(D5-C5)/ABS(C5) -> 0.093823614 | E32: =(E5-D5)/ABS(D5) -> 0.073694716 | F32: =(F5-E5)/ABS(E5) -> 0.058803385 | G32: =(G5-F5)/ABS(F5) -> -0.022224276 | H32: =(H5-G5)/ABS(G5) -> 0.16132691 | I32: =(I5-H5)/ABS(H5) -> 0.026652018 | J32: =(J5-I5)/ABS(I5) -> 0.1464072 | K32: =(K5-J5)/ABS(J5) -> -0.015557476 | R32: =(R5-M5)/ABS(M5) -> 0.11942594 | S32: =(S5-N5)/ABS(N5) -> -0.039399625 | T32: =(T5-O5)/ABS(O5) -> 0.029443065 | U32: =(U5-P5)/ABS(P5) -> 0.0062789655 | W32: =(W5-R5)/ABS(R5) -> 0.079365079 | X32: =(X5-S5)/ABS(S5) -> 0.23763021 | Y32: =(Y5-T5)/ABS(T5) -> 0.20933839 | Z32: =(Z5-U5)/ABS(U5) -> 0.074134601 | AB32: =(AB5-W5)/ABS(W5) -> 0.020786199 | AC32: =(AC5-X5)/ABS(X5) -> -0.02459232 | AD32: =(AD5-Y5)/ABS(Y5) -> -0.021655506 | AE32: =(AE5-Z5)/ABS(Z5) -> -0.035684647
A33: Gross profit | C33: =(C6-B6)/ABS(B6) -> 0.06426388 | D33: =(D6-C6)/ABS(C6) -> 0.02277737 | E33: =(E6-D6)/ABS(D6) -> 0.042058516 | F33: =(F6-E6)/ABS(E6) -> 0.095136626 | G33: =(G6-F6)/ABS(F6) -> -0.070561978 | H33: =(H6-G6)/ABS(G6) -> 0.22911151 | I33: =(I6-H6)/ABS(H6) -> 0.075994389 | J33: =(J6-I6)/ABS(I6) -> 0.037850924 | K33: =(K6-J6)/ABS(J6) -> 0.02669119 | R33: =(R6-M6)/ABS(M6) -> 0.2014343 | S33: =(S6-N6)/ABS(N6) -> 0.075510625 | T33: =(T6-O6)/ABS(O6) -> 0.073744437 | U33: =(U6-P6)/ABS(P6) -> -0.026878868 | W33: =(W6-R6)/ABS(R6) -> -0.014220506 | X33: =(X6-S6)/ABS(S6) -> 0.095530405 | Y33: =(Y6-T6)/ABS(T6) -> 0.059996053 | Z33: =(Z6-U6)/ABS(U6) -> 0.016718154 | AB33: =(AB6-W6)/ABS(W6) -> 0.018699911 | AC33: =(AC6-X6)/ABS(X6) -> 0.045526178 | AD33: =(AD6-Y6)/ABS(Y6) -> 0.035561348 | AE33: =(AE6-Z6)/ABS(Z6) -> 0.0069705094
A34: Demand creation expense | C34: =(C7-B7)/ABS(B7) -> 0.020230314 | D34: =(D7-C7)/ABS(C7) -> 0.019219036 | E34: =(E7-D7)/ABS(D7) -> 0.070637534 | F34: =(F7-E7)/ABS(E7) -> 0.049203243 | G34: =(G7-F7)/ABS(F7) -> -0.042899014 | H34: =(H7-G7)/ABS(G7) -> -0.1330735 | I34: =(I7-H7)/ABS(H7) -> 0.23635196 | J34: =(J7-I7)/ABS(I7) -> 0.054545455 | K34: =(K7-J7)/ABS(J7) -> 0.055418719 | R34: =(R7-M7)/ABS(M7) -> 0.35598227 | S34: =(S7-N7)/ABS(N7) -> 0.39506173 | T34: =(T7-O7)/ABS(O7) -> 0.20112518 | U34: =(U7-P7)/ABS(P7) -> 0.064192578 | W34: =(W7-R7)/ABS(R7) -> 0.027233115 | X34: =(X7-S7)/ABS(S7) -> 0.083579154 | Y34: =(Y7-T7)/ABS(T7) -> 0.080796253 | Z34: =(Z7-U7)/ABS(U7) -> 0.029217719 | AB34: =(AB7-W7)/ABS(W7) -> 0.13361612 | AC34: =(AC7-X7)/ABS(X7) -> 0.010889292 | AD34: =(AD7-Y7)/ABS(Y7) -> 0.095341278 | AE34: =(AE7-Z7)/ABS(Z7) -> -0.00091575092
A35: Operating overhead expense | C35: =(C8-B8)/ABS(B8) -> 0.076658182 | D35: =(D8-C8)/ABS(C8) -> 0.0043109442 | E35: =(E8-D8)/ABS(D8) -> 0.098587649 | F35: =(F8-E8)/ABS(E8) -> 0.12793043 | G35: =(G8-F8)/ABS(F8) -> 0.065370432 | H35: =(H8-G8)/ABS(G8) -> 0.039542689 | I35: =(I8-H8)/ABS(H8) -> 0.10523661 | J35: =(J8-I8)/ABS(I8) -> 0.12442943 | K35: =(K8-J8)/ABS(J8) -> -0.0021109036 | R35: =(R8-M8)/ABS(M8) -> 0.15491732 | S35: =(S8-N8)/ABS(N8) -> 0.080378251 | T35: =(T8-O8)/ABS(O8) -> 0.10901288 | U35: =(U8-P8)/ABS(P8) -> 0.083424408 | W35: =(W8-R8)/ABS(R8) -> 0.12170309 | X35: =(X8-S8)/ABS(S8) -> 0.10211524 | Y35: =(Y8-T8)/ABS(T8) -> 0.1749226 | Z35: =(Z8-U8)/ABS(U8) -> 0.10356422 | AB35: =(AB8-W8)/ABS(W8) -> 0.023513604 | AC35: =(AC8-X8)/ABS(X8) -> 0.0033090668 | AD35: =(AD8-Y8)/ABS(Y8) -> 0.058959157 | AE35: =(AE8-Z8)/ABS(Z8) -> -0.086837294
A36: Total selling and administrative expense | C36: =(C9-B9)/ABS(B9) -> 0.058329964 | D36: =(D9-C9)/ABS(C9) -> 0.0089788901 | E36: =(E9-D9)/ABS(D9) -> 0.089747231 | F36: =(F9-E9)/ABS(E9) -> 0.10346625 | G36: =(G9-F9)/ABS(F9) -> 0.03338057 | H36: =(H9-G9)/ABS(G9) -> -0.0076946518 | I36: =(I9-H9)/ABS(H9) -> 0.13658349 | J36: =(J9-I9)/ABS(I9) -> 0.10625507 | K36: =(K9-J9)/ABS(J9) -> 0.012151188 | R36: =(R9-M9)/ABS(M9) -> 0.20067227 | S36: =(S9-N9)/ABS(N9) -> 0.15059688 | T36: =(T9-O9)/ABS(O9) -> 0.13054916 | U36: =(U9-P9)/ABS(P9) -> 0.078300374 | W36: =(W9-R9)/ABS(R9) -> 0.097424412 | X36: =(X9-S9)/ABS(S9) -> 0.097100293 | Y36: =(Y9-T9)/ABS(T9) -> 0.15154159 | Z36: =(Z9-U9)/ABS(U9) -> 0.08401487 | AB36: =(AB9-W9)/ABS(W9) -> 0.05 | AC36: =(AC9-X9)/ABS(X9) -> 0.0053346266 | AD36: =(AD9-Y9)/ABS(Y9) -> 0.067441273 | AE36: =(AE9-Z9)/ABS(Z9) -> -0.065386374
A37: Interest expense (income), net | C37: =(C11-B11)/ABS(B11) -> -0.32142857 | D37: =(D11-C11)/ABS(C11) -> 2.1052632 | E37: =(E11-D11)/ABS(D11) -> -0.084745763 | F37: =(F11-E11)/ABS(E11) -> -0.092592593 | G37: =(G11-F11)/ABS(F11) -> 0.81632653 | H37: =(H11-G11)/ABS(G11) -> 1.9438202 | I37: =(I11-H11)/ABS(H11) -> -0.21755725 | J37: =(J11-I11)/ABS(I11) -> -1.0292683 | K37: =(K11-J11)/ABS(J11) -> -25.833333 | R37: =(R11-M11)/ABS(M11) -> -0.12307692 | S37: =(S11-N11)/ABS(N11) -> -0.21428571 | T37: =(T11-O11)/ABS(O11) -> -0.171875 | U37: =(U11-P11)/ABS(P11) -> -0.36507937 | W37: =(W11-R11)/ABS(R11) -> -0.77192982 | X37: =(X11-S11)/ABS(S11) -> -0.70909091 | Y37: =(Y11-T11)/ABS(T11) -> -1.1320755 | Z37: =(Z11-U11)/ABS(U11) -> -1.7 | AB37: =(AB11-W11)/ABS(W11) -> -3.6153846 | AC37: =(AC11-X11)/ABS(X11) -> -2.375 | AD37: =(AD11-Y11)/ABS(Y11) -> -6.4285714 | AE37: =(AE11-Z11)/ABS(Z11) -> -0.89285714
A38: Other (income) expense, net | C38: =(C12-B12)/ABS(B12) -> -1.4137931 | D38: =(D12-C12)/ABS(C12) -> -0.4 | E38: =(E12-D12)/ABS(D12) -> 1.3367347 | F38: =(F12-E12)/ABS(E12) -> -2.1818182 | G38: =(G12-F12)/ABS(F12) -> 2.7820513 | H38: =(H12-G12)/ABS(G12) -> -0.89928058 | I38: =(I12-H12)/ABS(H12) -> -13.928571 | J38: =(J12-I12)/ABS(I12) -> -0.54696133 | K38: =(K12-J12)/ABS(J12) -> 0.18571429 | R38: =(R12-M12)/ABS(M12) -> -1.7857143 | S38: =(S12-N12)/ABS(N12) -> -2.8888889 | T38: =(T12-O12)/ABS(O12) -> -3.2727273 | U38: =(U12-P12)/ABS(P12) -> 14.5 | W38: =(W12-R12)/ABS(R12) -> -2.7435897 | X38: =(X12-S12)/ABS(S12) -> 0.2254902 | Y38: =(Y12-T12)/ABS(T12) -> 0.38297872 | Z38: =(Z12-U12)/ABS(U12) -> -0.94444444 | AB38: =(AB12-W12)/ABS(W12) -> 0.93150685 | AC38: =(AC12-X12)/ABS(X12) -> 0.050632911 | AD38: =(AD12-Y12)/ABS(Y12) -> 0.72413793 | AE38: =(AE12-Z12)/ABS(Z12) -> -43.333333
A39: Income before income taxes | C39: =(C13-B13)/ABS(B13) -> 0.09940547 | D39: =(D13-C13)/ABS(C13) -> 0.056889466 | E39: =(E13-D13)/ABS(D13) -> -0.11481785 | F39: =(F13-E13)/ABS(E13) -> 0.1100578 | G39: =(G13-F13)/ABS(F13) -> -0.39866694 | H39: =(H13-G13)/ABS(G13) -> 1.3072393 | I39: =(I13-H13)/ABS(H13) -> -0.0015012761 | J39: =(J13-I13)/ABS(I13) -> -0.067658999 | K39: =(K13-J13)/ABS(J13) -> 0.080470892 | R39: =(R13-M13)/ABS(M13) -> 0.22798834 | S39: =(S13-N13)/ABS(N13) -> 0.030906593 | T39: =(T13-O13)/ABS(O13) -> 0.020782396 | U39: =(U13-P13)/ABS(P13) -> -0.25889968 | W39: =(W13-R13)/ABS(R13) -> -0.1320038 | X39: =(X13-S13)/ABS(S13) -> 0.099267155 | Y39: =(Y13-T13)/ABS(T13) -> -0.11556886 | Z39: =(Z13-U13)/ABS(U13) -> -0.093158661 | AB39: =(AB13-W13)/ABS(W13) -> -0.098468271 | AC39: =(AC13-X13)/ABS(X13) -> 0.16484848 | AD39: =(AD13-Y13)/ABS(Y13) -> -0.049424509 | AE39: =(AE13-Z13)/ABS(Z13) -> 0.38523274
A40: Income tax expense | C40: =(C14-B14)/ABS(B14) -> -0.074034335 | D40: =(D14-C14)/ABS(C14) -> -0.25144844 | E40: =(E14-D14)/ABS(D14) -> 2.7027864 | F40: =(F14-E14)/ABS(E14) -> -0.67725753 | G40: =(G14-F14)/ABS(F14) -> -0.5492228 | H40: =(H14-G14)/ABS(G14) -> 1.683908 | I40: =(I14-H14)/ABS(H14) -> -0.35224839 | J40: =(J14-I14)/ABS(I14) -> 0.86942149 | K40: =(K14-J14)/ABS(J14) -> -0.1158267 | R40: =(R14-M14)/ABS(M14) -> 0.17766497 | S40: =(S14-N14)/ABS(N14) -> -0.2 | T40: =(T14-O14)/ABS(O14) -> 0.46524064 | U40: =(U14-P14)/ABS(P14) -> -1.1884058 | W40: =(W14-R14)/ABS(R14) -> 0.55172414 | X40: =(X14-S14)/ABS(S14) -> 0.94512195 | Y40: =(Y14-T14)/ABS(T14) -> -0.1350365 | Z40: =(Z14-U14)/ABS(U14) -> 4.3076923 | AB40: =(AB14-W14)/ABS(W14) -> -0.45 | AC40: =(AC14-X14)/ABS(X14) -> 0.078369906 | AD40: =(AD14-Y14)/ABS(Y14) -> -0.021097046 | AE40: =(AE14-Z14)/ABS(Z14) -> 0.051162791
A41: NET INCOME | C41: =(C15-B15)/ABS(B15) -> 0.14879316 | D41: =(D15-C15)/ABS(C15) -> 0.12765957 | E41: =(E15-D15)/ABS(D15) -> -0.54410377 | F41: =(F15-E15)/ABS(E15) -> 1.0843249 | G41: =(G15-F15)/ABS(F15) -> -0.36981881 | H41: =(H15-G15)/ABS(G15) -> 1.2556124 | I41: =(I15-H15)/ABS(H15) -> 0.055701065 | J41: =(J15-I15)/ABS(I15) -> -0.16142904 | K41: =(K15-J15)/ABS(J15) -> 0.12426036 | R41: =(R15-M15)/ABS(M15) -> 0.2345191 | S41: =(S15-N15)/ABS(N15) -> 0.068745004 | T41: =(T15-O15)/ABS(O15) -> -0.03657695 | U41: =(U15-P15)/ABS(P15) -> -0.046388337 | W41: =(W15-R15)/ABS(R15) -> -0.21664888 | X41: =(X15-S15)/ABS(S15) -> -0.0044876589 | Y41: =(Y15-T15)/ABS(T15) -> -0.11174785 | Z41: =(Z15-U15)/ABS(U15) -> -0.28353023 | AB41: =(AB15-W15)/ABS(W15) -> -0.01226158 | AC41: =(AC15-X15)/ABS(X15) -> 0.18557476 | AD41: =(AD15-Y15)/ABS(Y15) -> -0.05483871 | AE41: =(AE15-Z15)/ABS(Z15) -> 0.45489816
A42: Earnings per common share:
...

Sheet Statement of Cashflow
A1: Consolidated Statements of Cash Flows - USD ($) $ in Millions | B1: 12 Months Ended
B2: May 31, 2015 | C2: May 31, 2016 | D2: May 31, 2017 | E2: May 31, 2018 | F2: May 31, 2019 | G2: May 31, 2020 | H2: May 31, 2021 | I2: May 31, 2022 | J2: May 31, 2023 | K2: May 31, 2024 E | L2: May 31, 2024
A3: Cash provided (used) by operations:
A4: Net income | B4: 3273 | C4: 3760 | D4: 4240 | E4: 1933 | F4: 4029 | G4: 2539 | H4: 5727 | I4: 6046 | J4: 5070 | K4: ='Valuations & Forecasting'!K45 -> 5475.9 | L4: 5700
A5: Adjustments to reconcile net income to net cash provided (used) by operations:
A6: Depreciation | B6: 606 | C6: 649 | D6: 706 | E6: 747 | F6: 705 | G6: 721 | H6: 744 | I6: 717 | J6: 703 | L6: 796
A7: Deferred income taxes | B7: -113 | C7: -80 | D7: -273 | E7: 647 | F7: 34 | G7: -380 | H7: -385 | I7: -650 | J7: -117 | L7: -497
A8: Stock-based compensation | B8: 191 | C8: 236 | D8: 215 | E8: 218 | F8: 325 | G8: 429 | H8: 611 | I8: 638 | J8: 755 | L8: 804
A9: Amortization, impairment and other | B9: 43 | C9: 13 | D9: 10 | E9: 27 | F9: 15 | G9: 398 | H9: 53 | I9: 123 | J9: 156 | L9: 48
A10: Net foreign currency adjustments | B10: 424 | C10: 98 | D10: -117 | E10: -99 | F10: 233 | G10: 23 | H10: -138 | I10: -26 | J10: -213 | L10: -138
A11: Changes in certain working capital components and other assets and liabilities:
A13: (Increase) decrease in accounts receivable | B13: -216 | C13: 60 | D13: -426 | E13: 187 | F13: -270 | G13: 1239 | H13: -1606 | I13: -504 | J13: 489 | L13: -329
C14: =(C13-B13)/ABS(B13) -> 1.2777778 | D14: =(D13-C13)/ABS(C13) -> -8.1 | E14: =(E13-D13)/ABS(D13) -> 1.4389671 | F14: =(F13-E13)/ABS(E13) -> -2.4438503 | G14: =(G13-F13)/ABS(F13) -> 5.5888889 | H14: =(H13-G13)/ABS(G13) -> -2.2962066 | I14: =(I13-H13)/ABS(H13) -> 0.68617684 | J14: =(J13-I13)/ABS(I13) -> 1.9702381 | L14: =(L13-J13)/ABS(J13) -> -1.6728016
A15: (Increase) decrease in inventories | B15: -621 | C15: -590 | D15: -231 | E15: -255 | F15: -490 | G15: -1854 | H15: 507 | I15: -1676 | J15: -133 | L15: 908
C16: =(C15-B15)/ABS(B15) -> 0.049919485 | D16: =(D15-C15)/ABS(C15) -> 0.60847458 | E16: =(E15-D15)/ABS(D15) -> -0.1038961 | F16: =(F15-E15)/ABS(E15) -> -0.92156863 | G16: =(G15-F15)/ABS(F15) -> -2.7836735 | H16: =(H15-G15)/ABS(G15) -> 1.2734628 | I16: =(I15-H15)/ABS(H15) -> -4.3057199 | J16: =(J15-I15)/ABS(I15) -> 0.92064439 | L16: =(L15-J15)/ABS(J15) -> 7.8270677
A17: (Increase) decrease in prepaid expenses, operating lease right-of-use assets and other current and non-current assets | B17: -144 | C17: -161 | D17: -120 | E17: 35 | F17: -203 | G17: -654 | H17: -182 | I17: -845 | J17: -644 | L17: -260
C18: =(C17-B17)/ABS(B17) -> -0.11805556 | D18: =(D17-C17)/ABS(C17) -> 0.25465839 | E18: =(E17-D17)/ABS(D17) -> 1.2916667 | F18: =(F17-E17)/ABS(E17) -> -6.8 | G18: =(G17-F17)/ABS(F17) -> -2.2216749 | H18: =(H17-G17)/ABS(G17) -> 0.72171254 | I18: =(I17-H17)/ABS(H17) -> -3.6428571 | J18: =(J17-I17)/ABS(I17) -> 0.23786982 | L18: =(L17-J17)/ABS(J17) -> 0.59627329
A19: Increase (decrease) in accounts payable, accrued liabilities, operating lease liabilities and other current and non-current liabilities | B19: 1237 | C19: -889 | D19: -364 | E19: 1515 | F19: 1525 | G19: 24 | H19: 1326 | I19: 1365 | J19: -225 | L19: 397
C20: =(C19-B19)/ABS(B19) -> -1.7186742 | D20: =(D19-C19)/ABS(C19) -> 0.59055118 | E20: =(E19-D19)/ABS(D19) -> 5.1620879 | F20: =(F19-E19)/ABS(E19) -> 0.0066006601 | G20: =(G19-F19)/ABS(F19) -> -0.9842623 | H20: =(H19-G19)/ABS(G19) -> 54.25 | I20: =(I19-H19)/ABS(H19) -> 0.029411765 | J20: =(J19-I19)/ABS(I19) -> -1.1648352 | L20: =(L19-J19)/ABS(J19) -> 2.7644444
A21: Cash provided (used) by operations | B21: 4680 | C21: 3096 | D21: 3640 | E21: 4955 | F21: 5903 | G21: 2485 | H21: 6657 | I21: 5188 | J21: 5841 | L21: 7429
C22: =(C21-B21)/ABS(B21) -> -0.33846154 | D22: =(D21-C21)/ABS(C21) -> 0.17571059 | E22: =(E21-D21)/ABS(D21) -> 0.36126374 | F22: =(F21-E21)/ABS(E21) -> 0.1913219 | G22: =(G21-F21)/ABS(F21) -> -0.57902761 | H22: =(H21-G21)/ABS(G21) -> 1.6788732 | I22: =(I21-H21)/ABS(H21) -> -0.22066997 | J22: =(J21-I21)/ABS(I21) -> 0.12586739 | L22: =(L21-J21)/ABS(J21) -> 0.27187125
A23: Cash provided (used) by investing activities:
A24: Purchases of short-term investments | B24: -4936 | C24: -5367 | D24: -5928 | E24: -4783 | F24: -2937 | G24: -2426 | H24: -9961 | I24: -12913 | J24: -6059 | L24: -4767
A25: Maturities of short-term investments | B25: 3655 | C25: 2924 | D25: 3623 | E25: 3613 | F25: 1715 | G25: 74 | H25: 4236 | I25: 8199 | J25: 3356 | L25: 2269
A26: Sales of short-term investments | B26: 2216 | C26: 2386 | D26: 2423 | E26: 2496 | F26: 2072 | G26: 2379 | H26: 2449 | I26: 3967 | J26: 4184 | L26: 4219
A27: Investments in reverse repurchase agreements | B27: -150 | C27: 150 | D27: 0 | E27: 0 | F27: 0 | G27: 0 | H27: 0 | I27: 0 | J27: 0
A28: Additions to property, plant and equipment | B28: -963 | C28: -1143 | D28: -1105 | E28: -1028 | F28: -1119 | G28: -1086 | H28: -695 | I28: -758 | J28: -969 | L28: -812
A29: Disposals of property, plant and equipment | B29: 3 | C29: 10 | D29: 13 | E29: 0 | F29: 0 | G29: 0 | H29: 0 | I29: 0 | J29: 0
A30: Other investing activities | B30: 0 | C30: 6 | D30: -34 | E30: -22 | F30: 5 | G30: 31 | H30: 171 | I30: -19 | J30: 52 | L30: -15
A31: Cash provided (used) by investing activities | B31: -175 | C31: -1034 | D31: -1008 | E31: 276 | F31: -264 | G31: -1028 | H31: -3800 | I31: -1524 | J31: 564 | L31: 894
A32: Cash provided (used) by financing activities:
A33: Net proceeds from long-term debt issuance | B33: 0 | C33: 981 | D33: 1482 | E33: 0 | F33: 0 | G33: 6134 | H33: 0 | I33: 0 | J33: 0
A34: Long-term debt payments, including current portion | B34: -7 | C34: -106 | D34: -44 | E34: 0 | F34: 0 | G34: 0 | H34: 0 | I34: 0 | J34: 0
A35: Increase (decrease) in notes payable, net | B35: -63 | C35: -67 | D35: 327 | E35: 13 | F35: -325 | G35: 49 | H35: -52 | I35: 15 | J35: -4 | L35: 0
A36: Repayment of borrowings | B36: -19 | C36: -7 | D36: -17 | E36: 0 | F36: 0 | G36: 0 | H36: -197 | I36: 0 | J36: -500 | L36: 0
A37: Proceeds from exercise of stock options and other stock issuances | B37: 514 | C37: 507 | D37: 489 | E37: 733 | F37: 700 | G37: 885 | H37: 1172 | I37: 1151 | J37: 651 | L37: 667
A38: Repurchase of common stock | B38: 218 | C38: 281 | D38: 177 | E38: -4254 | F38: -4286 | G38: -3067 | H38: -608 | I38: -4014 | J38: -5480 | L38: -4250
A39: Dividends — common and preferred | B39: -2534 | C39: -3238 | D39: -3223 | E39: -1243 | F39: -1332 | G39: -1452 | H39: -1638 | I39: -1837 | J39: -2012 | L39: -2169
A40: Other financing activities | B40: -899 | C40: -1022 | D40: -1133 | E40: -84 | F40: -50 | G40: -58 | H40: -136 | I40: -151 | J40: -102 | L40: -136
A41: Cash provided (used) by financing activities | B41: -2790 | C41: -2671 | D41: -1942 | E41: -4835 | F41: -5293 | G41: 2491 | H41: -1459 | I41: -4836 | J41: -7447 | L41: -5888
...
